{
 "cells": [
  {
   "cell_type": "code",
   "execution_count": 34,
   "metadata": {
    "id": "8lpVdnId3iYM"
   },
   "outputs": [],
   "source": [
    "import pandas as pd\n",
    "import string\n",
    "import re\n",
    "\n",
    "from tensorflow.keras.preprocessing.text import Tokenizer\n",
    "from tensorflow.keras.preprocessing.sequence import pad_sequences\n",
    "from sklearn.model_selection import train_test_split\n",
    "# from tqdm import tqdm\n",
    "# from tensorflow.keras.preprocessing.text import one_hot"
   ]
  },
  {
   "cell_type": "code",
   "execution_count": 23,
   "metadata": {},
   "outputs": [],
   "source": [
    "# The maximum number of words to be used. (most frequent)\n",
    "MAX_NB_WORDS = 50000\n",
    "# Max number of words in each doc.\n",
    "MAX_SEQUENCE_LENGTH = 5489\n",
    "# This is fixed.\n",
    "EMBEDDING_DIM = 100"
   ]
  },
  {
   "cell_type": "code",
   "execution_count": 3,
   "metadata": {},
   "outputs": [],
   "source": [
    "df = pd.read_csv(r'./data/parsed_data.csv')"
   ]
  },
  {
   "cell_type": "code",
   "execution_count": 20,
   "metadata": {},
   "outputs": [],
   "source": [
    "f = [len(x.split()) for x in df['body']]"
   ]
  },
  {
   "cell_type": "code",
   "execution_count": 22,
   "metadata": {},
   "outputs": [
    {
     "data": {
      "text/plain": [
       "5489"
      ]
     },
     "execution_count": 22,
     "metadata": {},
     "output_type": "execute_result"
    }
   ],
   "source": [
    "max(f)"
   ]
  },
  {
   "cell_type": "code",
   "execution_count": 4,
   "metadata": {},
   "outputs": [],
   "source": [
    "df['label'] = df['label'].apply(lambda x: x.lower())\n",
    "\n",
    "true_labels = ['correct attribution','mostly true','mostly-true', 'true',]\n",
    "false_labels = ['false','mostly false','pants-fire',]\n",
    "temp=[]\n",
    "for index in range(len(df)):\n",
    "    if df['label'][index] in true_labels:\n",
    "        temp.append(0)\n",
    "    elif df['label'][index] in false_labels:\n",
    "        temp.append(1)\n",
    "    else:\n",
    "        temp.append(2)\n",
    "        \n",
    "df['new_label']=temp"
   ]
  },
  {
   "cell_type": "code",
   "execution_count": 31,
   "metadata": {},
   "outputs": [],
   "source": [
    "Y = pd.get_dummies(df['new_label']).values"
   ]
  },
  {
   "cell_type": "code",
   "execution_count": 24,
   "metadata": {},
   "outputs": [
    {
     "name": "stdout",
     "output_type": "stream",
     "text": [
      "Found 86738 unique tokens.\n"
     ]
    }
   ],
   "source": [
    "tokenizer = Tokenizer()\n",
    "tokenizer.fit_on_texts(df['body'].values)\n",
    "X = tokenizer.texts_to_sequences(df['body'].values)\n",
    "word_index = tokenizer.word_index\n",
    "print('Found %s unique tokens.' % len(word_index))"
   ]
  },
  {
   "cell_type": "code",
   "execution_count": 27,
   "metadata": {},
   "outputs": [
    {
     "name": "stdout",
     "output_type": "stream",
     "text": [
      "Shape of data tensor: (22298, 5489)\n"
     ]
    }
   ],
   "source": [
    "X = pad_sequences(X, maxlen=MAX_SEQUENCE_LENGTH)\n",
    "print('Shape of data tensor:', X.shape)"
   ]
  },
  {
   "cell_type": "code",
   "execution_count": 35,
   "metadata": {},
   "outputs": [
    {
     "name": "stdout",
     "output_type": "stream",
     "text": [
      "(20068, 5489) (20068, 3)\n",
      "(2230, 5489) (2230, 3)\n"
     ]
    }
   ],
   "source": [
    "X_train, X_test, Y_train, Y_test = train_test_split(X,Y, test_size = 0.10, random_state = 42)\n",
    "print(X_train.shape,Y_train.shape)\n",
    "print(X_test.shape,Y_test.shape)"
   ]
  },
  {
   "cell_type": "code",
   "execution_count": 11,
   "metadata": {
    "id": "iktM29u5-pjx"
   },
   "outputs": [],
   "source": [
    "from tensorflow.keras.layers import Embedding\n",
    "from tensorflow.keras.preprocessing.sequence import pad_sequences\n",
    "from tensorflow.keras.models import Sequential\n",
    "from tensorflow.keras.layers import Dense\n",
    "from tensorflow.keras.layers import LSTM\n",
    "\n",
    "import numpy as np"
   ]
  },
  {
   "cell_type": "code",
   "execution_count": 13,
   "metadata": {
    "id": "E7T2E-9CBChI"
   },
   "outputs": [],
   "source": [
    "embedding_vector_fetures = 100\n",
    "vocab_size = 5000\n",
    "\n",
    "model = Sequential()\n",
    "model.add(Embedding(vocab_size,embedding_vector_fetures,input_length= MAX_SEQUENCE_LENGTH))\n",
    "model.add(LSTM(64, dropout=0.2, recurrent_dropout=0.2))#LSTM(100))\n",
    "model.add(Dense(3, activation = 'softmax'))\n",
    "model.compile(loss = 'categorical_crossentropy', optimizer = 'adam', metrics = ['accuracy'])"
   ]
  },
  {
   "cell_type": "code",
   "execution_count": 14,
   "metadata": {
    "colab": {
     "base_uri": "https://localhost:8080/"
    },
    "id": "OYAr3SuvCz0x",
    "outputId": "7667dd44-b552-40fa-97aa-9532e5695c38"
   },
   "outputs": [
    {
     "name": "stdout",
     "output_type": "stream",
     "text": [
      "Model: \"sequential\"\n",
      "_________________________________________________________________\n",
      " Layer (type)                Output Shape              Param #   \n",
      "=================================================================\n",
      " embedding (Embedding)       (None, 300, 64)           320000    \n",
      "                                                                 \n",
      " lstm (LSTM)                 (None, 64)                33024     \n",
      "                                                                 \n",
      " dense (Dense)               (None, 24)                1560      \n",
      "                                                                 \n",
      "=================================================================\n",
      "Total params: 354,584\n",
      "Trainable params: 354,584\n",
      "Non-trainable params: 0\n",
      "_________________________________________________________________\n"
     ]
    }
   ],
   "source": [
    "model.summary()"
   ]
  },
  {
   "cell_type": "code",
   "execution_count": 15,
   "metadata": {
    "colab": {
     "base_uri": "https://localhost:8080/"
    },
    "id": "EQJqrcPRDCnf",
    "outputId": "0d7a5546-8fa0-4ea3-c0bf-6c564e049c44"
   },
   "outputs": [],
   "source": [
    "final_x = np.array(embedded_docs)\n",
    "final_y = np.array(td['label'])"
   ]
  },
  {
   "cell_type": "code",
   "execution_count": 17,
   "metadata": {},
   "outputs": [
    {
     "name": "stdout",
     "output_type": "stream",
     "text": [
      "(17838, 300) (4460, 300) (17838,) (4460,)\n"
     ]
    }
   ],
   "source": [
    "from sklearn.model_selection import train_test_split\n",
    "x_train, x_test, y_train, y_test = train_test_split(final_x, final_y, test_size = 0.2, random_state = 42)\n",
    "print(x_train.shape, x_test.shape, y_train.shape, y_test.shape)\n"
   ]
  },
  {
   "cell_type": "code",
   "execution_count": 20,
   "metadata": {},
   "outputs": [],
   "source": [
    "import tensorflow as tf\n",
    "final_y_train = tf.keras.utils.to_categorical(y_train, num_classes=24)\n",
    "final_y_test = tf.keras.utils.to_categorical(y_test, num_classes=24)"
   ]
  },
  {
   "cell_type": "code",
   "execution_count": 21,
   "metadata": {},
   "outputs": [
    {
     "name": "stdout",
     "output_type": "stream",
     "text": [
      "(17838, 24) (4460, 24)\n"
     ]
    }
   ],
   "source": [
    "print(final_y_train.shape, final_y_test.shape)"
   ]
  },
  {
   "cell_type": "code",
   "execution_count": 22,
   "metadata": {},
   "outputs": [
    {
     "name": "stdout",
     "output_type": "stream",
     "text": [
      "Epoch 1/10\n"
     ]
    },
    {
     "name": "stderr",
     "output_type": "stream",
     "text": [
      "2023-04-08 19:45:22.609345: I tensorflow/core/common_runtime/executor.cc:1197] [/job:localhost/replica:0/task:0/device:CPU:0] (DEBUG INFO) Executor start aborting (this does not indicate an error and you can ignore this message): INVALID_ARGUMENT: indices[20,205] = 7518 is not in [0, 5000)\n",
      "\t [[{{node sequential/embedding/embedding_lookup}}]]\n"
     ]
    },
    {
     "ename": "InvalidArgumentError",
     "evalue": "Graph execution error:\n\nDetected at node 'sequential/embedding/embedding_lookup' defined at (most recent call last):\n    File \"/home/ubuntu/miniconda3/envs/tf/lib/python3.9/runpy.py\", line 197, in _run_module_as_main\n      return _run_code(code, main_globals, None,\n    File \"/home/ubuntu/miniconda3/envs/tf/lib/python3.9/runpy.py\", line 87, in _run_code\n      exec(code, run_globals)\n    File \"/home/ubuntu/miniconda3/envs/tf/lib/python3.9/site-packages/ipykernel_launcher.py\", line 17, in <module>\n      app.launch_new_instance()\n    File \"/home/ubuntu/miniconda3/envs/tf/lib/python3.9/site-packages/traitlets/config/application.py\", line 992, in launch_instance\n      app.start()\n    File \"/home/ubuntu/miniconda3/envs/tf/lib/python3.9/site-packages/ipykernel/kernelapp.py\", line 711, in start\n      self.io_loop.start()\n    File \"/home/ubuntu/miniconda3/envs/tf/lib/python3.9/site-packages/tornado/platform/asyncio.py\", line 215, in start\n      self.asyncio_loop.run_forever()\n    File \"/home/ubuntu/miniconda3/envs/tf/lib/python3.9/asyncio/base_events.py\", line 601, in run_forever\n      self._run_once()\n    File \"/home/ubuntu/miniconda3/envs/tf/lib/python3.9/asyncio/base_events.py\", line 1905, in _run_once\n      handle._run()\n    File \"/home/ubuntu/miniconda3/envs/tf/lib/python3.9/asyncio/events.py\", line 80, in _run\n      self._context.run(self._callback, *self._args)\n    File \"/home/ubuntu/miniconda3/envs/tf/lib/python3.9/site-packages/ipykernel/kernelbase.py\", line 510, in dispatch_queue\n      await self.process_one()\n    File \"/home/ubuntu/miniconda3/envs/tf/lib/python3.9/site-packages/ipykernel/kernelbase.py\", line 499, in process_one\n      await dispatch(*args)\n    File \"/home/ubuntu/miniconda3/envs/tf/lib/python3.9/site-packages/ipykernel/kernelbase.py\", line 406, in dispatch_shell\n      await result\n    File \"/home/ubuntu/miniconda3/envs/tf/lib/python3.9/site-packages/ipykernel/kernelbase.py\", line 729, in execute_request\n      reply_content = await reply_content\n    File \"/home/ubuntu/miniconda3/envs/tf/lib/python3.9/site-packages/ipykernel/ipkernel.py\", line 411, in do_execute\n      res = shell.run_cell(\n    File \"/home/ubuntu/miniconda3/envs/tf/lib/python3.9/site-packages/ipykernel/zmqshell.py\", line 531, in run_cell\n      return super().run_cell(*args, **kwargs)\n    File \"/home/ubuntu/miniconda3/envs/tf/lib/python3.9/site-packages/IPython/core/interactiveshell.py\", line 3006, in run_cell\n      result = self._run_cell(\n    File \"/home/ubuntu/miniconda3/envs/tf/lib/python3.9/site-packages/IPython/core/interactiveshell.py\", line 3061, in _run_cell\n      result = runner(coro)\n    File \"/home/ubuntu/miniconda3/envs/tf/lib/python3.9/site-packages/IPython/core/async_helpers.py\", line 129, in _pseudo_sync_runner\n      coro.send(None)\n    File \"/home/ubuntu/miniconda3/envs/tf/lib/python3.9/site-packages/IPython/core/interactiveshell.py\", line 3266, in run_cell_async\n      has_raised = await self.run_ast_nodes(code_ast.body, cell_name,\n    File \"/home/ubuntu/miniconda3/envs/tf/lib/python3.9/site-packages/IPython/core/interactiveshell.py\", line 3445, in run_ast_nodes\n      if await self.run_code(code, result, async_=asy):\n    File \"/home/ubuntu/miniconda3/envs/tf/lib/python3.9/site-packages/IPython/core/interactiveshell.py\", line 3505, in run_code\n      exec(code_obj, self.user_global_ns, self.user_ns)\n    File \"/tmp/ipykernel_30336/2957581064.py\", line 1, in <module>\n      model.fit(x_train, final_y_train, batch_size=32, epochs=10, validation_data=(x_test,final_y_test))\n    File \"/home/ubuntu/miniconda3/envs/tf/lib/python3.9/site-packages/keras/utils/traceback_utils.py\", line 65, in error_handler\n      return fn(*args, **kwargs)\n    File \"/home/ubuntu/miniconda3/envs/tf/lib/python3.9/site-packages/keras/engine/training.py\", line 1685, in fit\n      tmp_logs = self.train_function(iterator)\n    File \"/home/ubuntu/miniconda3/envs/tf/lib/python3.9/site-packages/keras/engine/training.py\", line 1284, in train_function\n      return step_function(self, iterator)\n    File \"/home/ubuntu/miniconda3/envs/tf/lib/python3.9/site-packages/keras/engine/training.py\", line 1268, in step_function\n      outputs = model.distribute_strategy.run(run_step, args=(data,))\n    File \"/home/ubuntu/miniconda3/envs/tf/lib/python3.9/site-packages/keras/engine/training.py\", line 1249, in run_step\n      outputs = model.train_step(data)\n    File \"/home/ubuntu/miniconda3/envs/tf/lib/python3.9/site-packages/keras/engine/training.py\", line 1050, in train_step\n      y_pred = self(x, training=True)\n    File \"/home/ubuntu/miniconda3/envs/tf/lib/python3.9/site-packages/keras/utils/traceback_utils.py\", line 65, in error_handler\n      return fn(*args, **kwargs)\n    File \"/home/ubuntu/miniconda3/envs/tf/lib/python3.9/site-packages/keras/engine/training.py\", line 558, in __call__\n      return super().__call__(*args, **kwargs)\n    File \"/home/ubuntu/miniconda3/envs/tf/lib/python3.9/site-packages/keras/utils/traceback_utils.py\", line 65, in error_handler\n      return fn(*args, **kwargs)\n    File \"/home/ubuntu/miniconda3/envs/tf/lib/python3.9/site-packages/keras/engine/base_layer.py\", line 1145, in __call__\n      outputs = call_fn(inputs, *args, **kwargs)\n    File \"/home/ubuntu/miniconda3/envs/tf/lib/python3.9/site-packages/keras/utils/traceback_utils.py\", line 96, in error_handler\n      return fn(*args, **kwargs)\n    File \"/home/ubuntu/miniconda3/envs/tf/lib/python3.9/site-packages/keras/engine/sequential.py\", line 412, in call\n      return super().call(inputs, training=training, mask=mask)\n    File \"/home/ubuntu/miniconda3/envs/tf/lib/python3.9/site-packages/keras/engine/functional.py\", line 512, in call\n      return self._run_internal_graph(inputs, training=training, mask=mask)\n    File \"/home/ubuntu/miniconda3/envs/tf/lib/python3.9/site-packages/keras/engine/functional.py\", line 669, in _run_internal_graph\n      outputs = node.layer(*args, **kwargs)\n    File \"/home/ubuntu/miniconda3/envs/tf/lib/python3.9/site-packages/keras/utils/traceback_utils.py\", line 65, in error_handler\n      return fn(*args, **kwargs)\n    File \"/home/ubuntu/miniconda3/envs/tf/lib/python3.9/site-packages/keras/engine/base_layer.py\", line 1145, in __call__\n      outputs = call_fn(inputs, *args, **kwargs)\n    File \"/home/ubuntu/miniconda3/envs/tf/lib/python3.9/site-packages/keras/utils/traceback_utils.py\", line 96, in error_handler\n      return fn(*args, **kwargs)\n    File \"/home/ubuntu/miniconda3/envs/tf/lib/python3.9/site-packages/keras/layers/core/embedding.py\", line 272, in call\n      out = tf.nn.embedding_lookup(self.embeddings, inputs)\nNode: 'sequential/embedding/embedding_lookup'\nindices[20,205] = 7518 is not in [0, 5000)\n\t [[{{node sequential/embedding/embedding_lookup}}]] [Op:__inference_train_function_4240]",
     "output_type": "error",
     "traceback": [
      "\u001b[0;31m---------------------------------------------------------------------------\u001b[0m",
      "\u001b[0;31mInvalidArgumentError\u001b[0m                      Traceback (most recent call last)",
      "Cell \u001b[0;32mIn[22], line 1\u001b[0m\n\u001b[0;32m----> 1\u001b[0m \u001b[43mmodel\u001b[49m\u001b[38;5;241;43m.\u001b[39;49m\u001b[43mfit\u001b[49m\u001b[43m(\u001b[49m\u001b[43mx_train\u001b[49m\u001b[43m,\u001b[49m\u001b[43m \u001b[49m\u001b[43mfinal_y_train\u001b[49m\u001b[43m,\u001b[49m\u001b[43m \u001b[49m\u001b[43mbatch_size\u001b[49m\u001b[38;5;241;43m=\u001b[39;49m\u001b[38;5;241;43m32\u001b[39;49m\u001b[43m,\u001b[49m\u001b[43m \u001b[49m\u001b[43mepochs\u001b[49m\u001b[38;5;241;43m=\u001b[39;49m\u001b[38;5;241;43m10\u001b[39;49m\u001b[43m,\u001b[49m\u001b[43m \u001b[49m\u001b[43mvalidation_data\u001b[49m\u001b[38;5;241;43m=\u001b[39;49m\u001b[43m(\u001b[49m\u001b[43mx_test\u001b[49m\u001b[43m,\u001b[49m\u001b[43mfinal_y_test\u001b[49m\u001b[43m)\u001b[49m\u001b[43m)\u001b[49m\n",
      "File \u001b[0;32m~/miniconda3/envs/tf/lib/python3.9/site-packages/keras/utils/traceback_utils.py:70\u001b[0m, in \u001b[0;36mfilter_traceback.<locals>.error_handler\u001b[0;34m(*args, **kwargs)\u001b[0m\n\u001b[1;32m     67\u001b[0m     filtered_tb \u001b[38;5;241m=\u001b[39m _process_traceback_frames(e\u001b[38;5;241m.\u001b[39m__traceback__)\n\u001b[1;32m     68\u001b[0m     \u001b[38;5;66;03m# To get the full stack trace, call:\u001b[39;00m\n\u001b[1;32m     69\u001b[0m     \u001b[38;5;66;03m# `tf.debugging.disable_traceback_filtering()`\u001b[39;00m\n\u001b[0;32m---> 70\u001b[0m     \u001b[38;5;28;01mraise\u001b[39;00m e\u001b[38;5;241m.\u001b[39mwith_traceback(filtered_tb) \u001b[38;5;28;01mfrom\u001b[39;00m \u001b[38;5;28mNone\u001b[39m\n\u001b[1;32m     71\u001b[0m \u001b[38;5;28;01mfinally\u001b[39;00m:\n\u001b[1;32m     72\u001b[0m     \u001b[38;5;28;01mdel\u001b[39;00m filtered_tb\n",
      "File \u001b[0;32m~/miniconda3/envs/tf/lib/python3.9/site-packages/tensorflow/python/eager/execute.py:52\u001b[0m, in \u001b[0;36mquick_execute\u001b[0;34m(op_name, num_outputs, inputs, attrs, ctx, name)\u001b[0m\n\u001b[1;32m     50\u001b[0m \u001b[38;5;28;01mtry\u001b[39;00m:\n\u001b[1;32m     51\u001b[0m   ctx\u001b[38;5;241m.\u001b[39mensure_initialized()\n\u001b[0;32m---> 52\u001b[0m   tensors \u001b[38;5;241m=\u001b[39m pywrap_tfe\u001b[38;5;241m.\u001b[39mTFE_Py_Execute(ctx\u001b[38;5;241m.\u001b[39m_handle, device_name, op_name,\n\u001b[1;32m     53\u001b[0m                                       inputs, attrs, num_outputs)\n\u001b[1;32m     54\u001b[0m \u001b[38;5;28;01mexcept\u001b[39;00m core\u001b[38;5;241m.\u001b[39m_NotOkStatusException \u001b[38;5;28;01mas\u001b[39;00m e:\n\u001b[1;32m     55\u001b[0m   \u001b[38;5;28;01mif\u001b[39;00m name \u001b[38;5;129;01mis\u001b[39;00m \u001b[38;5;129;01mnot\u001b[39;00m \u001b[38;5;28;01mNone\u001b[39;00m:\n",
      "\u001b[0;31mInvalidArgumentError\u001b[0m: Graph execution error:\n\nDetected at node 'sequential/embedding/embedding_lookup' defined at (most recent call last):\n    File \"/home/ubuntu/miniconda3/envs/tf/lib/python3.9/runpy.py\", line 197, in _run_module_as_main\n      return _run_code(code, main_globals, None,\n    File \"/home/ubuntu/miniconda3/envs/tf/lib/python3.9/runpy.py\", line 87, in _run_code\n      exec(code, run_globals)\n    File \"/home/ubuntu/miniconda3/envs/tf/lib/python3.9/site-packages/ipykernel_launcher.py\", line 17, in <module>\n      app.launch_new_instance()\n    File \"/home/ubuntu/miniconda3/envs/tf/lib/python3.9/site-packages/traitlets/config/application.py\", line 992, in launch_instance\n      app.start()\n    File \"/home/ubuntu/miniconda3/envs/tf/lib/python3.9/site-packages/ipykernel/kernelapp.py\", line 711, in start\n      self.io_loop.start()\n    File \"/home/ubuntu/miniconda3/envs/tf/lib/python3.9/site-packages/tornado/platform/asyncio.py\", line 215, in start\n      self.asyncio_loop.run_forever()\n    File \"/home/ubuntu/miniconda3/envs/tf/lib/python3.9/asyncio/base_events.py\", line 601, in run_forever\n      self._run_once()\n    File \"/home/ubuntu/miniconda3/envs/tf/lib/python3.9/asyncio/base_events.py\", line 1905, in _run_once\n      handle._run()\n    File \"/home/ubuntu/miniconda3/envs/tf/lib/python3.9/asyncio/events.py\", line 80, in _run\n      self._context.run(self._callback, *self._args)\n    File \"/home/ubuntu/miniconda3/envs/tf/lib/python3.9/site-packages/ipykernel/kernelbase.py\", line 510, in dispatch_queue\n      await self.process_one()\n    File \"/home/ubuntu/miniconda3/envs/tf/lib/python3.9/site-packages/ipykernel/kernelbase.py\", line 499, in process_one\n      await dispatch(*args)\n    File \"/home/ubuntu/miniconda3/envs/tf/lib/python3.9/site-packages/ipykernel/kernelbase.py\", line 406, in dispatch_shell\n      await result\n    File \"/home/ubuntu/miniconda3/envs/tf/lib/python3.9/site-packages/ipykernel/kernelbase.py\", line 729, in execute_request\n      reply_content = await reply_content\n    File \"/home/ubuntu/miniconda3/envs/tf/lib/python3.9/site-packages/ipykernel/ipkernel.py\", line 411, in do_execute\n      res = shell.run_cell(\n    File \"/home/ubuntu/miniconda3/envs/tf/lib/python3.9/site-packages/ipykernel/zmqshell.py\", line 531, in run_cell\n      return super().run_cell(*args, **kwargs)\n    File \"/home/ubuntu/miniconda3/envs/tf/lib/python3.9/site-packages/IPython/core/interactiveshell.py\", line 3006, in run_cell\n      result = self._run_cell(\n    File \"/home/ubuntu/miniconda3/envs/tf/lib/python3.9/site-packages/IPython/core/interactiveshell.py\", line 3061, in _run_cell\n      result = runner(coro)\n    File \"/home/ubuntu/miniconda3/envs/tf/lib/python3.9/site-packages/IPython/core/async_helpers.py\", line 129, in _pseudo_sync_runner\n      coro.send(None)\n    File \"/home/ubuntu/miniconda3/envs/tf/lib/python3.9/site-packages/IPython/core/interactiveshell.py\", line 3266, in run_cell_async\n      has_raised = await self.run_ast_nodes(code_ast.body, cell_name,\n    File \"/home/ubuntu/miniconda3/envs/tf/lib/python3.9/site-packages/IPython/core/interactiveshell.py\", line 3445, in run_ast_nodes\n      if await self.run_code(code, result, async_=asy):\n    File \"/home/ubuntu/miniconda3/envs/tf/lib/python3.9/site-packages/IPython/core/interactiveshell.py\", line 3505, in run_code\n      exec(code_obj, self.user_global_ns, self.user_ns)\n    File \"/tmp/ipykernel_30336/2957581064.py\", line 1, in <module>\n      model.fit(x_train, final_y_train, batch_size=32, epochs=10, validation_data=(x_test,final_y_test))\n    File \"/home/ubuntu/miniconda3/envs/tf/lib/python3.9/site-packages/keras/utils/traceback_utils.py\", line 65, in error_handler\n      return fn(*args, **kwargs)\n    File \"/home/ubuntu/miniconda3/envs/tf/lib/python3.9/site-packages/keras/engine/training.py\", line 1685, in fit\n      tmp_logs = self.train_function(iterator)\n    File \"/home/ubuntu/miniconda3/envs/tf/lib/python3.9/site-packages/keras/engine/training.py\", line 1284, in train_function\n      return step_function(self, iterator)\n    File \"/home/ubuntu/miniconda3/envs/tf/lib/python3.9/site-packages/keras/engine/training.py\", line 1268, in step_function\n      outputs = model.distribute_strategy.run(run_step, args=(data,))\n    File \"/home/ubuntu/miniconda3/envs/tf/lib/python3.9/site-packages/keras/engine/training.py\", line 1249, in run_step\n      outputs = model.train_step(data)\n    File \"/home/ubuntu/miniconda3/envs/tf/lib/python3.9/site-packages/keras/engine/training.py\", line 1050, in train_step\n      y_pred = self(x, training=True)\n    File \"/home/ubuntu/miniconda3/envs/tf/lib/python3.9/site-packages/keras/utils/traceback_utils.py\", line 65, in error_handler\n      return fn(*args, **kwargs)\n    File \"/home/ubuntu/miniconda3/envs/tf/lib/python3.9/site-packages/keras/engine/training.py\", line 558, in __call__\n      return super().__call__(*args, **kwargs)\n    File \"/home/ubuntu/miniconda3/envs/tf/lib/python3.9/site-packages/keras/utils/traceback_utils.py\", line 65, in error_handler\n      return fn(*args, **kwargs)\n    File \"/home/ubuntu/miniconda3/envs/tf/lib/python3.9/site-packages/keras/engine/base_layer.py\", line 1145, in __call__\n      outputs = call_fn(inputs, *args, **kwargs)\n    File \"/home/ubuntu/miniconda3/envs/tf/lib/python3.9/site-packages/keras/utils/traceback_utils.py\", line 96, in error_handler\n      return fn(*args, **kwargs)\n    File \"/home/ubuntu/miniconda3/envs/tf/lib/python3.9/site-packages/keras/engine/sequential.py\", line 412, in call\n      return super().call(inputs, training=training, mask=mask)\n    File \"/home/ubuntu/miniconda3/envs/tf/lib/python3.9/site-packages/keras/engine/functional.py\", line 512, in call\n      return self._run_internal_graph(inputs, training=training, mask=mask)\n    File \"/home/ubuntu/miniconda3/envs/tf/lib/python3.9/site-packages/keras/engine/functional.py\", line 669, in _run_internal_graph\n      outputs = node.layer(*args, **kwargs)\n    File \"/home/ubuntu/miniconda3/envs/tf/lib/python3.9/site-packages/keras/utils/traceback_utils.py\", line 65, in error_handler\n      return fn(*args, **kwargs)\n    File \"/home/ubuntu/miniconda3/envs/tf/lib/python3.9/site-packages/keras/engine/base_layer.py\", line 1145, in __call__\n      outputs = call_fn(inputs, *args, **kwargs)\n    File \"/home/ubuntu/miniconda3/envs/tf/lib/python3.9/site-packages/keras/utils/traceback_utils.py\", line 96, in error_handler\n      return fn(*args, **kwargs)\n    File \"/home/ubuntu/miniconda3/envs/tf/lib/python3.9/site-packages/keras/layers/core/embedding.py\", line 272, in call\n      out = tf.nn.embedding_lookup(self.embeddings, inputs)\nNode: 'sequential/embedding/embedding_lookup'\nindices[20,205] = 7518 is not in [0, 5000)\n\t [[{{node sequential/embedding/embedding_lookup}}]] [Op:__inference_train_function_4240]"
     ]
    }
   ],
   "source": [
    "model.fit(x_train, final_y_train, batch_size=32, epochs=10, validation_data=(x_test,final_y_test))"
   ]
  },
  {
   "cell_type": "code",
   "execution_count": 23,
   "metadata": {},
   "outputs": [
    {
     "name": "stdout",
     "output_type": "stream",
     "text": [
      "Epoch 1/10\n"
     ]
    },
    {
     "name": "stderr",
     "output_type": "stream",
     "text": [
      "2023-04-08 19:45:40.715815: I tensorflow/core/common_runtime/executor.cc:1197] [/job:localhost/replica:0/task:0/device:CPU:0] (DEBUG INFO) Executor start aborting (this does not indicate an error and you can ignore this message): INVALID_ARGUMENT: indices[37,101] = 6656 is not in [0, 5000)\n",
      "\t [[{{node sequential/embedding/embedding_lookup}}]]\n"
     ]
    },
    {
     "ename": "InvalidArgumentError",
     "evalue": "Graph execution error:\n\nDetected at node 'sequential/embedding/embedding_lookup' defined at (most recent call last):\n    File \"/home/ubuntu/miniconda3/envs/tf/lib/python3.9/runpy.py\", line 197, in _run_module_as_main\n      return _run_code(code, main_globals, None,\n    File \"/home/ubuntu/miniconda3/envs/tf/lib/python3.9/runpy.py\", line 87, in _run_code\n      exec(code, run_globals)\n    File \"/home/ubuntu/miniconda3/envs/tf/lib/python3.9/site-packages/ipykernel_launcher.py\", line 17, in <module>\n      app.launch_new_instance()\n    File \"/home/ubuntu/miniconda3/envs/tf/lib/python3.9/site-packages/traitlets/config/application.py\", line 992, in launch_instance\n      app.start()\n    File \"/home/ubuntu/miniconda3/envs/tf/lib/python3.9/site-packages/ipykernel/kernelapp.py\", line 711, in start\n      self.io_loop.start()\n    File \"/home/ubuntu/miniconda3/envs/tf/lib/python3.9/site-packages/tornado/platform/asyncio.py\", line 215, in start\n      self.asyncio_loop.run_forever()\n    File \"/home/ubuntu/miniconda3/envs/tf/lib/python3.9/asyncio/base_events.py\", line 601, in run_forever\n      self._run_once()\n    File \"/home/ubuntu/miniconda3/envs/tf/lib/python3.9/asyncio/base_events.py\", line 1905, in _run_once\n      handle._run()\n    File \"/home/ubuntu/miniconda3/envs/tf/lib/python3.9/asyncio/events.py\", line 80, in _run\n      self._context.run(self._callback, *self._args)\n    File \"/home/ubuntu/miniconda3/envs/tf/lib/python3.9/site-packages/ipykernel/kernelbase.py\", line 510, in dispatch_queue\n      await self.process_one()\n    File \"/home/ubuntu/miniconda3/envs/tf/lib/python3.9/site-packages/ipykernel/kernelbase.py\", line 499, in process_one\n      await dispatch(*args)\n    File \"/home/ubuntu/miniconda3/envs/tf/lib/python3.9/site-packages/ipykernel/kernelbase.py\", line 406, in dispatch_shell\n      await result\n    File \"/home/ubuntu/miniconda3/envs/tf/lib/python3.9/site-packages/ipykernel/kernelbase.py\", line 729, in execute_request\n      reply_content = await reply_content\n    File \"/home/ubuntu/miniconda3/envs/tf/lib/python3.9/site-packages/ipykernel/ipkernel.py\", line 411, in do_execute\n      res = shell.run_cell(\n    File \"/home/ubuntu/miniconda3/envs/tf/lib/python3.9/site-packages/ipykernel/zmqshell.py\", line 531, in run_cell\n      return super().run_cell(*args, **kwargs)\n    File \"/home/ubuntu/miniconda3/envs/tf/lib/python3.9/site-packages/IPython/core/interactiveshell.py\", line 3006, in run_cell\n      result = self._run_cell(\n    File \"/home/ubuntu/miniconda3/envs/tf/lib/python3.9/site-packages/IPython/core/interactiveshell.py\", line 3061, in _run_cell\n      result = runner(coro)\n    File \"/home/ubuntu/miniconda3/envs/tf/lib/python3.9/site-packages/IPython/core/async_helpers.py\", line 129, in _pseudo_sync_runner\n      coro.send(None)\n    File \"/home/ubuntu/miniconda3/envs/tf/lib/python3.9/site-packages/IPython/core/interactiveshell.py\", line 3266, in run_cell_async\n      has_raised = await self.run_ast_nodes(code_ast.body, cell_name,\n    File \"/home/ubuntu/miniconda3/envs/tf/lib/python3.9/site-packages/IPython/core/interactiveshell.py\", line 3445, in run_ast_nodes\n      if await self.run_code(code, result, async_=asy):\n    File \"/home/ubuntu/miniconda3/envs/tf/lib/python3.9/site-packages/IPython/core/interactiveshell.py\", line 3505, in run_code\n      exec(code_obj, self.user_global_ns, self.user_ns)\n    File \"/tmp/ipykernel_30336/3697547531.py\", line 1, in <module>\n      model.fit(x_train, y_train, validation_data = (x_test,y_test), epochs = 10,batch_size = 64)\n    File \"/home/ubuntu/miniconda3/envs/tf/lib/python3.9/site-packages/keras/utils/traceback_utils.py\", line 65, in error_handler\n      return fn(*args, **kwargs)\n    File \"/home/ubuntu/miniconda3/envs/tf/lib/python3.9/site-packages/keras/engine/training.py\", line 1685, in fit\n      tmp_logs = self.train_function(iterator)\n    File \"/home/ubuntu/miniconda3/envs/tf/lib/python3.9/site-packages/keras/engine/training.py\", line 1284, in train_function\n      return step_function(self, iterator)\n    File \"/home/ubuntu/miniconda3/envs/tf/lib/python3.9/site-packages/keras/engine/training.py\", line 1268, in step_function\n      outputs = model.distribute_strategy.run(run_step, args=(data,))\n    File \"/home/ubuntu/miniconda3/envs/tf/lib/python3.9/site-packages/keras/engine/training.py\", line 1249, in run_step\n      outputs = model.train_step(data)\n    File \"/home/ubuntu/miniconda3/envs/tf/lib/python3.9/site-packages/keras/engine/training.py\", line 1050, in train_step\n      y_pred = self(x, training=True)\n    File \"/home/ubuntu/miniconda3/envs/tf/lib/python3.9/site-packages/keras/utils/traceback_utils.py\", line 65, in error_handler\n      return fn(*args, **kwargs)\n    File \"/home/ubuntu/miniconda3/envs/tf/lib/python3.9/site-packages/keras/engine/training.py\", line 558, in __call__\n      return super().__call__(*args, **kwargs)\n    File \"/home/ubuntu/miniconda3/envs/tf/lib/python3.9/site-packages/keras/utils/traceback_utils.py\", line 65, in error_handler\n      return fn(*args, **kwargs)\n    File \"/home/ubuntu/miniconda3/envs/tf/lib/python3.9/site-packages/keras/engine/base_layer.py\", line 1145, in __call__\n      outputs = call_fn(inputs, *args, **kwargs)\n    File \"/home/ubuntu/miniconda3/envs/tf/lib/python3.9/site-packages/keras/utils/traceback_utils.py\", line 96, in error_handler\n      return fn(*args, **kwargs)\n    File \"/home/ubuntu/miniconda3/envs/tf/lib/python3.9/site-packages/keras/engine/sequential.py\", line 412, in call\n      return super().call(inputs, training=training, mask=mask)\n    File \"/home/ubuntu/miniconda3/envs/tf/lib/python3.9/site-packages/keras/engine/functional.py\", line 512, in call\n      return self._run_internal_graph(inputs, training=training, mask=mask)\n    File \"/home/ubuntu/miniconda3/envs/tf/lib/python3.9/site-packages/keras/engine/functional.py\", line 669, in _run_internal_graph\n      outputs = node.layer(*args, **kwargs)\n    File \"/home/ubuntu/miniconda3/envs/tf/lib/python3.9/site-packages/keras/utils/traceback_utils.py\", line 65, in error_handler\n      return fn(*args, **kwargs)\n    File \"/home/ubuntu/miniconda3/envs/tf/lib/python3.9/site-packages/keras/engine/base_layer.py\", line 1145, in __call__\n      outputs = call_fn(inputs, *args, **kwargs)\n    File \"/home/ubuntu/miniconda3/envs/tf/lib/python3.9/site-packages/keras/utils/traceback_utils.py\", line 96, in error_handler\n      return fn(*args, **kwargs)\n    File \"/home/ubuntu/miniconda3/envs/tf/lib/python3.9/site-packages/keras/layers/core/embedding.py\", line 272, in call\n      out = tf.nn.embedding_lookup(self.embeddings, inputs)\nNode: 'sequential/embedding/embedding_lookup'\nindices[37,101] = 6656 is not in [0, 5000)\n\t [[{{node sequential/embedding/embedding_lookup}}]] [Op:__inference_train_function_6464]",
     "output_type": "error",
     "traceback": [
      "\u001b[0;31m---------------------------------------------------------------------------\u001b[0m",
      "\u001b[0;31mInvalidArgumentError\u001b[0m                      Traceback (most recent call last)",
      "Cell \u001b[0;32mIn[23], line 1\u001b[0m\n\u001b[0;32m----> 1\u001b[0m \u001b[43mmodel\u001b[49m\u001b[38;5;241;43m.\u001b[39;49m\u001b[43mfit\u001b[49m\u001b[43m(\u001b[49m\u001b[43mx_train\u001b[49m\u001b[43m,\u001b[49m\u001b[43m \u001b[49m\u001b[43my_train\u001b[49m\u001b[43m,\u001b[49m\u001b[43m \u001b[49m\u001b[43mvalidation_data\u001b[49m\u001b[43m \u001b[49m\u001b[38;5;241;43m=\u001b[39;49m\u001b[43m \u001b[49m\u001b[43m(\u001b[49m\u001b[43mx_test\u001b[49m\u001b[43m,\u001b[49m\u001b[43my_test\u001b[49m\u001b[43m)\u001b[49m\u001b[43m,\u001b[49m\u001b[43m \u001b[49m\u001b[43mepochs\u001b[49m\u001b[43m \u001b[49m\u001b[38;5;241;43m=\u001b[39;49m\u001b[43m \u001b[49m\u001b[38;5;241;43m10\u001b[39;49m\u001b[43m,\u001b[49m\u001b[43mbatch_size\u001b[49m\u001b[43m \u001b[49m\u001b[38;5;241;43m=\u001b[39;49m\u001b[43m \u001b[49m\u001b[38;5;241;43m64\u001b[39;49m\u001b[43m)\u001b[49m\n",
      "File \u001b[0;32m~/miniconda3/envs/tf/lib/python3.9/site-packages/keras/utils/traceback_utils.py:70\u001b[0m, in \u001b[0;36mfilter_traceback.<locals>.error_handler\u001b[0;34m(*args, **kwargs)\u001b[0m\n\u001b[1;32m     67\u001b[0m     filtered_tb \u001b[38;5;241m=\u001b[39m _process_traceback_frames(e\u001b[38;5;241m.\u001b[39m__traceback__)\n\u001b[1;32m     68\u001b[0m     \u001b[38;5;66;03m# To get the full stack trace, call:\u001b[39;00m\n\u001b[1;32m     69\u001b[0m     \u001b[38;5;66;03m# `tf.debugging.disable_traceback_filtering()`\u001b[39;00m\n\u001b[0;32m---> 70\u001b[0m     \u001b[38;5;28;01mraise\u001b[39;00m e\u001b[38;5;241m.\u001b[39mwith_traceback(filtered_tb) \u001b[38;5;28;01mfrom\u001b[39;00m \u001b[38;5;28mNone\u001b[39m\n\u001b[1;32m     71\u001b[0m \u001b[38;5;28;01mfinally\u001b[39;00m:\n\u001b[1;32m     72\u001b[0m     \u001b[38;5;28;01mdel\u001b[39;00m filtered_tb\n",
      "File \u001b[0;32m~/miniconda3/envs/tf/lib/python3.9/site-packages/tensorflow/python/eager/execute.py:52\u001b[0m, in \u001b[0;36mquick_execute\u001b[0;34m(op_name, num_outputs, inputs, attrs, ctx, name)\u001b[0m\n\u001b[1;32m     50\u001b[0m \u001b[38;5;28;01mtry\u001b[39;00m:\n\u001b[1;32m     51\u001b[0m   ctx\u001b[38;5;241m.\u001b[39mensure_initialized()\n\u001b[0;32m---> 52\u001b[0m   tensors \u001b[38;5;241m=\u001b[39m pywrap_tfe\u001b[38;5;241m.\u001b[39mTFE_Py_Execute(ctx\u001b[38;5;241m.\u001b[39m_handle, device_name, op_name,\n\u001b[1;32m     53\u001b[0m                                       inputs, attrs, num_outputs)\n\u001b[1;32m     54\u001b[0m \u001b[38;5;28;01mexcept\u001b[39;00m core\u001b[38;5;241m.\u001b[39m_NotOkStatusException \u001b[38;5;28;01mas\u001b[39;00m e:\n\u001b[1;32m     55\u001b[0m   \u001b[38;5;28;01mif\u001b[39;00m name \u001b[38;5;129;01mis\u001b[39;00m \u001b[38;5;129;01mnot\u001b[39;00m \u001b[38;5;28;01mNone\u001b[39;00m:\n",
      "\u001b[0;31mInvalidArgumentError\u001b[0m: Graph execution error:\n\nDetected at node 'sequential/embedding/embedding_lookup' defined at (most recent call last):\n    File \"/home/ubuntu/miniconda3/envs/tf/lib/python3.9/runpy.py\", line 197, in _run_module_as_main\n      return _run_code(code, main_globals, None,\n    File \"/home/ubuntu/miniconda3/envs/tf/lib/python3.9/runpy.py\", line 87, in _run_code\n      exec(code, run_globals)\n    File \"/home/ubuntu/miniconda3/envs/tf/lib/python3.9/site-packages/ipykernel_launcher.py\", line 17, in <module>\n      app.launch_new_instance()\n    File \"/home/ubuntu/miniconda3/envs/tf/lib/python3.9/site-packages/traitlets/config/application.py\", line 992, in launch_instance\n      app.start()\n    File \"/home/ubuntu/miniconda3/envs/tf/lib/python3.9/site-packages/ipykernel/kernelapp.py\", line 711, in start\n      self.io_loop.start()\n    File \"/home/ubuntu/miniconda3/envs/tf/lib/python3.9/site-packages/tornado/platform/asyncio.py\", line 215, in start\n      self.asyncio_loop.run_forever()\n    File \"/home/ubuntu/miniconda3/envs/tf/lib/python3.9/asyncio/base_events.py\", line 601, in run_forever\n      self._run_once()\n    File \"/home/ubuntu/miniconda3/envs/tf/lib/python3.9/asyncio/base_events.py\", line 1905, in _run_once\n      handle._run()\n    File \"/home/ubuntu/miniconda3/envs/tf/lib/python3.9/asyncio/events.py\", line 80, in _run\n      self._context.run(self._callback, *self._args)\n    File \"/home/ubuntu/miniconda3/envs/tf/lib/python3.9/site-packages/ipykernel/kernelbase.py\", line 510, in dispatch_queue\n      await self.process_one()\n    File \"/home/ubuntu/miniconda3/envs/tf/lib/python3.9/site-packages/ipykernel/kernelbase.py\", line 499, in process_one\n      await dispatch(*args)\n    File \"/home/ubuntu/miniconda3/envs/tf/lib/python3.9/site-packages/ipykernel/kernelbase.py\", line 406, in dispatch_shell\n      await result\n    File \"/home/ubuntu/miniconda3/envs/tf/lib/python3.9/site-packages/ipykernel/kernelbase.py\", line 729, in execute_request\n      reply_content = await reply_content\n    File \"/home/ubuntu/miniconda3/envs/tf/lib/python3.9/site-packages/ipykernel/ipkernel.py\", line 411, in do_execute\n      res = shell.run_cell(\n    File \"/home/ubuntu/miniconda3/envs/tf/lib/python3.9/site-packages/ipykernel/zmqshell.py\", line 531, in run_cell\n      return super().run_cell(*args, **kwargs)\n    File \"/home/ubuntu/miniconda3/envs/tf/lib/python3.9/site-packages/IPython/core/interactiveshell.py\", line 3006, in run_cell\n      result = self._run_cell(\n    File \"/home/ubuntu/miniconda3/envs/tf/lib/python3.9/site-packages/IPython/core/interactiveshell.py\", line 3061, in _run_cell\n      result = runner(coro)\n    File \"/home/ubuntu/miniconda3/envs/tf/lib/python3.9/site-packages/IPython/core/async_helpers.py\", line 129, in _pseudo_sync_runner\n      coro.send(None)\n    File \"/home/ubuntu/miniconda3/envs/tf/lib/python3.9/site-packages/IPython/core/interactiveshell.py\", line 3266, in run_cell_async\n      has_raised = await self.run_ast_nodes(code_ast.body, cell_name,\n    File \"/home/ubuntu/miniconda3/envs/tf/lib/python3.9/site-packages/IPython/core/interactiveshell.py\", line 3445, in run_ast_nodes\n      if await self.run_code(code, result, async_=asy):\n    File \"/home/ubuntu/miniconda3/envs/tf/lib/python3.9/site-packages/IPython/core/interactiveshell.py\", line 3505, in run_code\n      exec(code_obj, self.user_global_ns, self.user_ns)\n    File \"/tmp/ipykernel_30336/3697547531.py\", line 1, in <module>\n      model.fit(x_train, y_train, validation_data = (x_test,y_test), epochs = 10,batch_size = 64)\n    File \"/home/ubuntu/miniconda3/envs/tf/lib/python3.9/site-packages/keras/utils/traceback_utils.py\", line 65, in error_handler\n      return fn(*args, **kwargs)\n    File \"/home/ubuntu/miniconda3/envs/tf/lib/python3.9/site-packages/keras/engine/training.py\", line 1685, in fit\n      tmp_logs = self.train_function(iterator)\n    File \"/home/ubuntu/miniconda3/envs/tf/lib/python3.9/site-packages/keras/engine/training.py\", line 1284, in train_function\n      return step_function(self, iterator)\n    File \"/home/ubuntu/miniconda3/envs/tf/lib/python3.9/site-packages/keras/engine/training.py\", line 1268, in step_function\n      outputs = model.distribute_strategy.run(run_step, args=(data,))\n    File \"/home/ubuntu/miniconda3/envs/tf/lib/python3.9/site-packages/keras/engine/training.py\", line 1249, in run_step\n      outputs = model.train_step(data)\n    File \"/home/ubuntu/miniconda3/envs/tf/lib/python3.9/site-packages/keras/engine/training.py\", line 1050, in train_step\n      y_pred = self(x, training=True)\n    File \"/home/ubuntu/miniconda3/envs/tf/lib/python3.9/site-packages/keras/utils/traceback_utils.py\", line 65, in error_handler\n      return fn(*args, **kwargs)\n    File \"/home/ubuntu/miniconda3/envs/tf/lib/python3.9/site-packages/keras/engine/training.py\", line 558, in __call__\n      return super().__call__(*args, **kwargs)\n    File \"/home/ubuntu/miniconda3/envs/tf/lib/python3.9/site-packages/keras/utils/traceback_utils.py\", line 65, in error_handler\n      return fn(*args, **kwargs)\n    File \"/home/ubuntu/miniconda3/envs/tf/lib/python3.9/site-packages/keras/engine/base_layer.py\", line 1145, in __call__\n      outputs = call_fn(inputs, *args, **kwargs)\n    File \"/home/ubuntu/miniconda3/envs/tf/lib/python3.9/site-packages/keras/utils/traceback_utils.py\", line 96, in error_handler\n      return fn(*args, **kwargs)\n    File \"/home/ubuntu/miniconda3/envs/tf/lib/python3.9/site-packages/keras/engine/sequential.py\", line 412, in call\n      return super().call(inputs, training=training, mask=mask)\n    File \"/home/ubuntu/miniconda3/envs/tf/lib/python3.9/site-packages/keras/engine/functional.py\", line 512, in call\n      return self._run_internal_graph(inputs, training=training, mask=mask)\n    File \"/home/ubuntu/miniconda3/envs/tf/lib/python3.9/site-packages/keras/engine/functional.py\", line 669, in _run_internal_graph\n      outputs = node.layer(*args, **kwargs)\n    File \"/home/ubuntu/miniconda3/envs/tf/lib/python3.9/site-packages/keras/utils/traceback_utils.py\", line 65, in error_handler\n      return fn(*args, **kwargs)\n    File \"/home/ubuntu/miniconda3/envs/tf/lib/python3.9/site-packages/keras/engine/base_layer.py\", line 1145, in __call__\n      outputs = call_fn(inputs, *args, **kwargs)\n    File \"/home/ubuntu/miniconda3/envs/tf/lib/python3.9/site-packages/keras/utils/traceback_utils.py\", line 96, in error_handler\n      return fn(*args, **kwargs)\n    File \"/home/ubuntu/miniconda3/envs/tf/lib/python3.9/site-packages/keras/layers/core/embedding.py\", line 272, in call\n      out = tf.nn.embedding_lookup(self.embeddings, inputs)\nNode: 'sequential/embedding/embedding_lookup'\nindices[37,101] = 6656 is not in [0, 5000)\n\t [[{{node sequential/embedding/embedding_lookup}}]] [Op:__inference_train_function_6464]"
     ]
    }
   ],
   "source": [
    "model.fit(x_train, y_train, validation_data = (x_test,y_test), epochs = 10,batch_size = 64)"
   ]
  }
 ],
 "metadata": {
  "colab": {
   "provenance": []
  },
  "kernelspec": {
   "display_name": "tf",
   "language": "python",
   "name": "python3"
  },
  "language_info": {
   "codemirror_mode": {
    "name": "ipython",
    "version": 3
   },
   "file_extension": ".py",
   "mimetype": "text/x-python",
   "name": "python",
   "nbconvert_exporter": "python",
   "pygments_lexer": "ipython3",
   "version": "3.10.1"
  }
 },
 "nbformat": 4,
 "nbformat_minor": 1
}
