{
 "cells": [
  {
   "cell_type": "code",
   "execution_count": 1,
   "metadata": {
    "id": "8lpVdnId3iYM"
   },
   "outputs": [
    {
     "name": "stderr",
     "output_type": "stream",
     "text": [
      "2023-04-23 12:56:39.428351: I tensorflow/tsl/cuda/cudart_stub.cc:28] Could not find cuda drivers on your machine, GPU will not be used.\n",
      "2023-04-23 12:56:41.833671: I tensorflow/tsl/cuda/cudart_stub.cc:28] Could not find cuda drivers on your machine, GPU will not be used.\n",
      "2023-04-23 12:56:41.834483: I tensorflow/core/platform/cpu_feature_guard.cc:182] This TensorFlow binary is optimized to use available CPU instructions in performance-critical operations.\n",
      "To enable the following instructions: AVX2 FMA, in other operations, rebuild TensorFlow with the appropriate compiler flags.\n",
      "2023-04-23 12:56:43.702774: W tensorflow/compiler/tf2tensorrt/utils/py_utils.cc:38] TF-TRT Warning: Could not find TensorRT\n"
     ]
    }
   ],
   "source": [
    "import pandas as pd\n",
    "import string\n",
    "import re\n",
    "from tqdm import tqdm\n",
    "from tensorflow.keras.preprocessing.text import one_hot"
   ]
  },
  {
   "cell_type": "code",
   "execution_count": 2,
   "metadata": {
    "id": "VSLcswUI3iYP"
   },
   "outputs": [],
   "source": [
    "politifact = pd.read_json(r'./data/politifact.json')\n",
    "snopes = pd.read_json(r'./data/snopes.json')"
   ]
  },
  {
   "cell_type": "code",
   "execution_count": 5,
   "metadata": {
    "id": "owxJjfnX3iYQ"
   },
   "outputs": [],
   "source": [
    "# column names\n",
    "poli_cols = politifact.columns.to_list()\n",
    "snop_cols = snopes.columns.to_list()"
   ]
  },
  {
   "cell_type": "code",
   "execution_count": 7,
   "metadata": {},
   "outputs": [
    {
     "name": "stdout",
     "output_type": "stream",
     "text": [
      "{'false', 'full-flop', 'half-true', 'barely-true', 'half-flip', 'mostly-true', 'no-flip', 'pants-fire', 'true'}\n",
      "{'Unproven', 'Labeled Satire', 'Miscaptioned', 'Outdated', 'Correct Attribution', 'Scam', 'True', 'Mostly True', 'Misattributed', 'False', 'Research In Progress', 'Lost Legend', 'Mixture', 'Legend', 'Mostly False'}\n"
     ]
    }
   ],
   "source": [
    "a = set(list(politifact['label']))\n",
    "b = set(list(snopes['label']))\n",
    "print(a)\n",
    "print(b)"
   ]
  },
  {
   "cell_type": "code",
   "execution_count": 5,
   "metadata": {
    "id": "2xM1yD6v3iYQ"
   },
   "outputs": [],
   "source": [
    "common_cols = set(poli_cols) & set(snop_cols)\n",
    "\n",
    "td = pd.concat([snopes[list(common_cols)], politifact[list(common_cols)]])\n",
    "td = td.reindex(columns = ['doc', 'claim', 'factchecker', 'url', 'sources', 'topic', 'published' ,'label' ])\n"
   ]
  },
  {
   "cell_type": "code",
   "execution_count": null,
   "metadata": {},
   "outputs": [],
   "source": [
    "import matplotlib.pyplot as plt\n",
    "%matplotlib inline\n",
    "\n",
    "# fig, (ax1, ax2) = plt.subplots(1,2, figsize=(10, 5))\n",
    "\n",
    "ld = td.groupby(by='label').size()\n",
    "# new_ld = df.groupby(by='new_label').size()\n",
    "\n",
    "\n",
    "plt.xticks(rotation='vertical')\n",
    "plt.plot(list(set(df['label'].tolist())), ld)\n",
    "# ax2.set_title('Old')\n",
    "\n",
    "\n",
    "# ax1.bar(['0','1','2'], new_ld)\n",
    "# ax1.set_title('New')\n",
    "\n",
    "\n",
    "\n",
    "# plt.show()"
   ]
  },
  {
   "cell_type": "code",
   "execution_count": 6,
   "metadata": {
    "id": "tn7FY5DF3iYR"
   },
   "outputs": [],
   "source": [
    "\n",
    "td['label'] = td['label'].map({\n",
    "    'Correct Attribution':0,\n",
    "    'False':1,\n",
    "    'Labeled Satire':2,\n",
    "    'Legend':3,\n",
    "    'Lost Legend':4,\n",
    "    'Misattributed':5,\n",
    "    'Miscaptioned':6,\n",
    "    'Mixture':7,\n",
    "    'Mostly False':8,\n",
    "    'Mostly True':9,\n",
    "    'Outdated':10,\n",
    "    'Research In Progress':11,\n",
    "    'Scam':12,\n",
    "    'True':13,\n",
    "    'Unproven':14,\n",
    "    'barely-true':15,\n",
    "    'false':16,\n",
    "    'full-flop':17,\n",
    "    'half-flip':18,\n",
    "    'half-true':19,\n",
    "    'mostly-true':20,\n",
    "    'no-flip':21,\n",
    "    'pants-fire':22,\n",
    "    'true':23}\n",
    " )"
   ]
  },
  {
   "cell_type": "code",
   "execution_count": 7,
   "metadata": {
    "colab": {
     "base_uri": "https://localhost:8080/"
    },
    "id": "pBX7czZ43iYR",
    "outputId": "71859cfa-7ca1-4da8-cf57-e55ac9182294"
   },
   "outputs": [
    {
     "name": "stderr",
     "output_type": "stream",
     "text": [
      "100%|██████████████████████████████████████████████████████████████████████████████████████████████████| 7/7 [03:24<00:00, 29.19s/it]\n"
     ]
    }
   ],
   "source": [
    "mt = {\n",
    "        '\\n':\" \",\n",
    "        \"'\":None,\n",
    "        '\"':None,\n",
    "        '“':None,\n",
    "        '”':None,\n",
    "        '’':None,\n",
    "        '‘':None\n",
    "    }\n",
    "for n in range(10):\n",
    "    mt[str(n)]=None\n",
    "\n",
    "for x in string.punctuation:\n",
    "    mt[x]=None\n",
    "cols = td.columns.to_list()\n",
    "cols.remove('label')\n",
    "\n",
    "# cleaning the first file\n",
    "for col in tqdm(cols):\n",
    "    for indx, x in enumerate(td[col]):\n",
    "        try:\n",
    "            td.loc[indx,col] = (x.translate(x.maketrans(mt))).lower()\n",
    "        except:\n",
    "            if x==None:\n",
    "                td.loc[indx,col] = \"\"\n",
    "            elif type(x) == list:\n",
    "                p = \" \".join(str(z) for z in x)\n",
    "                td.loc[indx,col] = p.translate(p.maketrans(mt)).lower()\n",
    "            else:\n",
    "                print(f\"column:{col}\\trow:{indx}\\tvalue: {x} is invalid\\tvalue type: {type(x)}\")"
   ]
  },
  {
   "cell_type": "code",
   "execution_count": 8,
   "metadata": {
    "id": "VBh43NDF3iYT"
   },
   "outputs": [],
   "source": [
    "td = td.dropna(subset=['doc','claim','label'])"
   ]
  },
  {
   "cell_type": "code",
   "execution_count": 9,
   "metadata": {
    "id": "jCUtLNtr3iYU"
   },
   "outputs": [],
   "source": [
    "one_hot_prep = [one_hot(series['claim']+' '+ series['doc'],10000) for _, series in td.iterrows()]"
   ]
  },
  {
   "cell_type": "code",
   "execution_count": 10,
   "metadata": {
    "colab": {
     "base_uri": "https://localhost:8080/"
    },
    "id": "Avb_FXSq_jcE",
    "outputId": "e4e13772-e7a3-45ef-e7e2-8cc4bce89608"
   },
   "outputs": [
    {
     "name": "stdout",
     "output_type": "stream",
     "text": [
      "6955\n"
     ]
    }
   ],
   "source": [
    "temp = [len(x) for x in one_hot_prep]\n",
    "print(max(temp))"
   ]
  },
  {
   "cell_type": "code",
   "execution_count": 11,
   "metadata": {
    "id": "iktM29u5-pjx"
   },
   "outputs": [],
   "source": [
    "from tensorflow.keras.layers import Embedding\n",
    "from tensorflow.keras.preprocessing.sequence import pad_sequences\n",
    "from tensorflow.keras.models import Sequential\n",
    "from tensorflow.keras.layers import Dense\n",
    "from tensorflow.keras.layers import LSTM\n",
    "\n",
    "import numpy as np"
   ]
  },
  {
   "cell_type": "code",
   "execution_count": 12,
   "metadata": {
    "id": "CPyK5DXF_wxJ"
   },
   "outputs": [],
   "source": [
    "sent_len = 300\n",
    "embedded_docs = pad_sequences(one_hot_prep,padding='post',truncating='post',maxlen=sent_len)"
   ]
  },
  {
   "cell_type": "code",
   "execution_count": 13,
   "metadata": {
    "id": "E7T2E-9CBChI"
   },
   "outputs": [],
   "source": [
    "embedding_vector_fetures = 64\n",
    "vocab_size = 5000\n",
    "\n",
    "model = Sequential()\n",
    "model.add(Embedding(vocab_size,embedding_vector_fetures,input_length= sent_len))\n",
    "model.add(LSTM(64, dropout=0.2, recurrent_dropout=0.2))#LSTM(100))\n",
    "model.add(Dense(24, activation = 'softmax'))\n",
    "model.compile(loss = 'categorical_crossentropy', optimizer = 'adam', metrics = ['accuracy'])"
   ]
  },
  {
   "cell_type": "code",
   "execution_count": 14,
   "metadata": {
    "colab": {
     "base_uri": "https://localhost:8080/"
    },
    "id": "OYAr3SuvCz0x",
    "outputId": "7667dd44-b552-40fa-97aa-9532e5695c38"
   },
   "outputs": [
    {
     "name": "stdout",
     "output_type": "stream",
     "text": [
      "Model: \"sequential\"\n",
      "_________________________________________________________________\n",
      " Layer (type)                Output Shape              Param #   \n",
      "=================================================================\n",
      " embedding (Embedding)       (None, 300, 64)           320000    \n",
      "                                                                 \n",
      " lstm (LSTM)                 (None, 64)                33024     \n",
      "                                                                 \n",
      " dense (Dense)               (None, 24)                1560      \n",
      "                                                                 \n",
      "=================================================================\n",
      "Total params: 354,584\n",
      "Trainable params: 354,584\n",
      "Non-trainable params: 0\n",
      "_________________________________________________________________\n"
     ]
    }
   ],
   "source": [
    "model.summary()"
   ]
  },
  {
   "cell_type": "code",
   "execution_count": 79,
   "metadata": {},
   "outputs": [],
   "source": [
    "# x,_ = td.shape\n",
    "\n",
    "# y = td['label']\n",
    "# new_y = np.zeros((x,24))\n",
    "\n",
    "# for i,r in enumerate(y):\n",
    "#     try:\n",
    "#         new_y[i][int(r)]=1\n",
    "#     except:\n",
    "#         print(i, y[i])\n",
    "    "
   ]
  },
  {
   "cell_type": "code",
   "execution_count": 85,
   "metadata": {},
   "outputs": [
    {
     "name": "stdout",
     "output_type": "stream",
     "text": [
      "22298\n"
     ]
    }
   ],
   "source": [
    "print(len(new_y))"
   ]
  },
  {
   "cell_type": "code",
   "execution_count": 15,
   "metadata": {
    "colab": {
     "base_uri": "https://localhost:8080/"
    },
    "id": "EQJqrcPRDCnf",
    "outputId": "0d7a5546-8fa0-4ea3-c0bf-6c564e049c44"
   },
   "outputs": [],
   "source": [
    "final_x = np.array(embedded_docs)\n",
    "final_y = np.array(td['label'])"
   ]
  },
  {
   "cell_type": "code",
   "execution_count": 17,
   "metadata": {},
   "outputs": [
    {
     "name": "stdout",
     "output_type": "stream",
     "text": [
      "(17838, 300) (4460, 300) (17838,) (4460,)\n"
     ]
    }
   ],
   "source": [
    "from sklearn.model_selection import train_test_split\n",
    "x_train, x_test, y_train, y_test = train_test_split(final_x, final_y, test_size = 0.2, random_state = 42)\n",
    "print(x_train.shape, x_test.shape, y_train.shape, y_test.shape)\n"
   ]
  },
  {
   "cell_type": "code",
   "execution_count": 20,
   "metadata": {},
   "outputs": [],
   "source": [
    "import tensorflow as tf\n",
    "final_y_train = tf.keras.utils.to_categorical(y_train, num_classes=24)\n",
    "final_y_test = tf.keras.utils.to_categorical(y_test, num_classes=24)"
   ]
  },
  {
   "cell_type": "code",
   "execution_count": 21,
   "metadata": {},
   "outputs": [
    {
     "name": "stdout",
     "output_type": "stream",
     "text": [
      "(17838, 24) (4460, 24)\n"
     ]
    }
   ],
   "source": [
    "print(final_y_train.shape, final_y_test.shape)"
   ]
  },
  {
   "cell_type": "code",
   "execution_count": 22,
   "metadata": {},
   "outputs": [
    {
     "name": "stdout",
     "output_type": "stream",
     "text": [
      "Epoch 1/10\n"
     ]
    },
    {
     "name": "stderr",
     "output_type": "stream",
     "text": [
      "2023-04-08 19:45:22.609345: I tensorflow/core/common_runtime/executor.cc:1197] [/job:localhost/replica:0/task:0/device:CPU:0] (DEBUG INFO) Executor start aborting (this does not indicate an error and you can ignore this message): INVALID_ARGUMENT: indices[20,205] = 7518 is not in [0, 5000)\n",
      "\t [[{{node sequential/embedding/embedding_lookup}}]]\n"
     ]
    },
    {
     "ename": "InvalidArgumentError",
     "evalue": "Graph execution error:\n\nDetected at node 'sequential/embedding/embedding_lookup' defined at (most recent call last):\n    File \"/home/ubuntu/miniconda3/envs/tf/lib/python3.9/runpy.py\", line 197, in _run_module_as_main\n      return _run_code(code, main_globals, None,\n    File \"/home/ubuntu/miniconda3/envs/tf/lib/python3.9/runpy.py\", line 87, in _run_code\n      exec(code, run_globals)\n    File \"/home/ubuntu/miniconda3/envs/tf/lib/python3.9/site-packages/ipykernel_launcher.py\", line 17, in <module>\n      app.launch_new_instance()\n    File \"/home/ubuntu/miniconda3/envs/tf/lib/python3.9/site-packages/traitlets/config/application.py\", line 992, in launch_instance\n      app.start()\n    File \"/home/ubuntu/miniconda3/envs/tf/lib/python3.9/site-packages/ipykernel/kernelapp.py\", line 711, in start\n      self.io_loop.start()\n    File \"/home/ubuntu/miniconda3/envs/tf/lib/python3.9/site-packages/tornado/platform/asyncio.py\", line 215, in start\n      self.asyncio_loop.run_forever()\n    File \"/home/ubuntu/miniconda3/envs/tf/lib/python3.9/asyncio/base_events.py\", line 601, in run_forever\n      self._run_once()\n    File \"/home/ubuntu/miniconda3/envs/tf/lib/python3.9/asyncio/base_events.py\", line 1905, in _run_once\n      handle._run()\n    File \"/home/ubuntu/miniconda3/envs/tf/lib/python3.9/asyncio/events.py\", line 80, in _run\n      self._context.run(self._callback, *self._args)\n    File \"/home/ubuntu/miniconda3/envs/tf/lib/python3.9/site-packages/ipykernel/kernelbase.py\", line 510, in dispatch_queue\n      await self.process_one()\n    File \"/home/ubuntu/miniconda3/envs/tf/lib/python3.9/site-packages/ipykernel/kernelbase.py\", line 499, in process_one\n      await dispatch(*args)\n    File \"/home/ubuntu/miniconda3/envs/tf/lib/python3.9/site-packages/ipykernel/kernelbase.py\", line 406, in dispatch_shell\n      await result\n    File \"/home/ubuntu/miniconda3/envs/tf/lib/python3.9/site-packages/ipykernel/kernelbase.py\", line 729, in execute_request\n      reply_content = await reply_content\n    File \"/home/ubuntu/miniconda3/envs/tf/lib/python3.9/site-packages/ipykernel/ipkernel.py\", line 411, in do_execute\n      res = shell.run_cell(\n    File \"/home/ubuntu/miniconda3/envs/tf/lib/python3.9/site-packages/ipykernel/zmqshell.py\", line 531, in run_cell\n      return super().run_cell(*args, **kwargs)\n    File \"/home/ubuntu/miniconda3/envs/tf/lib/python3.9/site-packages/IPython/core/interactiveshell.py\", line 3006, in run_cell\n      result = self._run_cell(\n    File \"/home/ubuntu/miniconda3/envs/tf/lib/python3.9/site-packages/IPython/core/interactiveshell.py\", line 3061, in _run_cell\n      result = runner(coro)\n    File \"/home/ubuntu/miniconda3/envs/tf/lib/python3.9/site-packages/IPython/core/async_helpers.py\", line 129, in _pseudo_sync_runner\n      coro.send(None)\n    File \"/home/ubuntu/miniconda3/envs/tf/lib/python3.9/site-packages/IPython/core/interactiveshell.py\", line 3266, in run_cell_async\n      has_raised = await self.run_ast_nodes(code_ast.body, cell_name,\n    File \"/home/ubuntu/miniconda3/envs/tf/lib/python3.9/site-packages/IPython/core/interactiveshell.py\", line 3445, in run_ast_nodes\n      if await self.run_code(code, result, async_=asy):\n    File \"/home/ubuntu/miniconda3/envs/tf/lib/python3.9/site-packages/IPython/core/interactiveshell.py\", line 3505, in run_code\n      exec(code_obj, self.user_global_ns, self.user_ns)\n    File \"/tmp/ipykernel_30336/2957581064.py\", line 1, in <module>\n      model.fit(x_train, final_y_train, batch_size=32, epochs=10, validation_data=(x_test,final_y_test))\n    File \"/home/ubuntu/miniconda3/envs/tf/lib/python3.9/site-packages/keras/utils/traceback_utils.py\", line 65, in error_handler\n      return fn(*args, **kwargs)\n    File \"/home/ubuntu/miniconda3/envs/tf/lib/python3.9/site-packages/keras/engine/training.py\", line 1685, in fit\n      tmp_logs = self.train_function(iterator)\n    File \"/home/ubuntu/miniconda3/envs/tf/lib/python3.9/site-packages/keras/engine/training.py\", line 1284, in train_function\n      return step_function(self, iterator)\n    File \"/home/ubuntu/miniconda3/envs/tf/lib/python3.9/site-packages/keras/engine/training.py\", line 1268, in step_function\n      outputs = model.distribute_strategy.run(run_step, args=(data,))\n    File \"/home/ubuntu/miniconda3/envs/tf/lib/python3.9/site-packages/keras/engine/training.py\", line 1249, in run_step\n      outputs = model.train_step(data)\n    File \"/home/ubuntu/miniconda3/envs/tf/lib/python3.9/site-packages/keras/engine/training.py\", line 1050, in train_step\n      y_pred = self(x, training=True)\n    File \"/home/ubuntu/miniconda3/envs/tf/lib/python3.9/site-packages/keras/utils/traceback_utils.py\", line 65, in error_handler\n      return fn(*args, **kwargs)\n    File \"/home/ubuntu/miniconda3/envs/tf/lib/python3.9/site-packages/keras/engine/training.py\", line 558, in __call__\n      return super().__call__(*args, **kwargs)\n    File \"/home/ubuntu/miniconda3/envs/tf/lib/python3.9/site-packages/keras/utils/traceback_utils.py\", line 65, in error_handler\n      return fn(*args, **kwargs)\n    File \"/home/ubuntu/miniconda3/envs/tf/lib/python3.9/site-packages/keras/engine/base_layer.py\", line 1145, in __call__\n      outputs = call_fn(inputs, *args, **kwargs)\n    File \"/home/ubuntu/miniconda3/envs/tf/lib/python3.9/site-packages/keras/utils/traceback_utils.py\", line 96, in error_handler\n      return fn(*args, **kwargs)\n    File \"/home/ubuntu/miniconda3/envs/tf/lib/python3.9/site-packages/keras/engine/sequential.py\", line 412, in call\n      return super().call(inputs, training=training, mask=mask)\n    File \"/home/ubuntu/miniconda3/envs/tf/lib/python3.9/site-packages/keras/engine/functional.py\", line 512, in call\n      return self._run_internal_graph(inputs, training=training, mask=mask)\n    File \"/home/ubuntu/miniconda3/envs/tf/lib/python3.9/site-packages/keras/engine/functional.py\", line 669, in _run_internal_graph\n      outputs = node.layer(*args, **kwargs)\n    File \"/home/ubuntu/miniconda3/envs/tf/lib/python3.9/site-packages/keras/utils/traceback_utils.py\", line 65, in error_handler\n      return fn(*args, **kwargs)\n    File \"/home/ubuntu/miniconda3/envs/tf/lib/python3.9/site-packages/keras/engine/base_layer.py\", line 1145, in __call__\n      outputs = call_fn(inputs, *args, **kwargs)\n    File \"/home/ubuntu/miniconda3/envs/tf/lib/python3.9/site-packages/keras/utils/traceback_utils.py\", line 96, in error_handler\n      return fn(*args, **kwargs)\n    File \"/home/ubuntu/miniconda3/envs/tf/lib/python3.9/site-packages/keras/layers/core/embedding.py\", line 272, in call\n      out = tf.nn.embedding_lookup(self.embeddings, inputs)\nNode: 'sequential/embedding/embedding_lookup'\nindices[20,205] = 7518 is not in [0, 5000)\n\t [[{{node sequential/embedding/embedding_lookup}}]] [Op:__inference_train_function_4240]",
     "output_type": "error",
     "traceback": [
      "\u001b[0;31m---------------------------------------------------------------------------\u001b[0m",
      "\u001b[0;31mInvalidArgumentError\u001b[0m                      Traceback (most recent call last)",
      "Cell \u001b[0;32mIn[22], line 1\u001b[0m\n\u001b[0;32m----> 1\u001b[0m \u001b[43mmodel\u001b[49m\u001b[38;5;241;43m.\u001b[39;49m\u001b[43mfit\u001b[49m\u001b[43m(\u001b[49m\u001b[43mx_train\u001b[49m\u001b[43m,\u001b[49m\u001b[43m \u001b[49m\u001b[43mfinal_y_train\u001b[49m\u001b[43m,\u001b[49m\u001b[43m \u001b[49m\u001b[43mbatch_size\u001b[49m\u001b[38;5;241;43m=\u001b[39;49m\u001b[38;5;241;43m32\u001b[39;49m\u001b[43m,\u001b[49m\u001b[43m \u001b[49m\u001b[43mepochs\u001b[49m\u001b[38;5;241;43m=\u001b[39;49m\u001b[38;5;241;43m10\u001b[39;49m\u001b[43m,\u001b[49m\u001b[43m \u001b[49m\u001b[43mvalidation_data\u001b[49m\u001b[38;5;241;43m=\u001b[39;49m\u001b[43m(\u001b[49m\u001b[43mx_test\u001b[49m\u001b[43m,\u001b[49m\u001b[43mfinal_y_test\u001b[49m\u001b[43m)\u001b[49m\u001b[43m)\u001b[49m\n",
      "File \u001b[0;32m~/miniconda3/envs/tf/lib/python3.9/site-packages/keras/utils/traceback_utils.py:70\u001b[0m, in \u001b[0;36mfilter_traceback.<locals>.error_handler\u001b[0;34m(*args, **kwargs)\u001b[0m\n\u001b[1;32m     67\u001b[0m     filtered_tb \u001b[38;5;241m=\u001b[39m _process_traceback_frames(e\u001b[38;5;241m.\u001b[39m__traceback__)\n\u001b[1;32m     68\u001b[0m     \u001b[38;5;66;03m# To get the full stack trace, call:\u001b[39;00m\n\u001b[1;32m     69\u001b[0m     \u001b[38;5;66;03m# `tf.debugging.disable_traceback_filtering()`\u001b[39;00m\n\u001b[0;32m---> 70\u001b[0m     \u001b[38;5;28;01mraise\u001b[39;00m e\u001b[38;5;241m.\u001b[39mwith_traceback(filtered_tb) \u001b[38;5;28;01mfrom\u001b[39;00m \u001b[38;5;28mNone\u001b[39m\n\u001b[1;32m     71\u001b[0m \u001b[38;5;28;01mfinally\u001b[39;00m:\n\u001b[1;32m     72\u001b[0m     \u001b[38;5;28;01mdel\u001b[39;00m filtered_tb\n",
      "File \u001b[0;32m~/miniconda3/envs/tf/lib/python3.9/site-packages/tensorflow/python/eager/execute.py:52\u001b[0m, in \u001b[0;36mquick_execute\u001b[0;34m(op_name, num_outputs, inputs, attrs, ctx, name)\u001b[0m\n\u001b[1;32m     50\u001b[0m \u001b[38;5;28;01mtry\u001b[39;00m:\n\u001b[1;32m     51\u001b[0m   ctx\u001b[38;5;241m.\u001b[39mensure_initialized()\n\u001b[0;32m---> 52\u001b[0m   tensors \u001b[38;5;241m=\u001b[39m pywrap_tfe\u001b[38;5;241m.\u001b[39mTFE_Py_Execute(ctx\u001b[38;5;241m.\u001b[39m_handle, device_name, op_name,\n\u001b[1;32m     53\u001b[0m                                       inputs, attrs, num_outputs)\n\u001b[1;32m     54\u001b[0m \u001b[38;5;28;01mexcept\u001b[39;00m core\u001b[38;5;241m.\u001b[39m_NotOkStatusException \u001b[38;5;28;01mas\u001b[39;00m e:\n\u001b[1;32m     55\u001b[0m   \u001b[38;5;28;01mif\u001b[39;00m name \u001b[38;5;129;01mis\u001b[39;00m \u001b[38;5;129;01mnot\u001b[39;00m \u001b[38;5;28;01mNone\u001b[39;00m:\n",
      "\u001b[0;31mInvalidArgumentError\u001b[0m: Graph execution error:\n\nDetected at node 'sequential/embedding/embedding_lookup' defined at (most recent call last):\n    File \"/home/ubuntu/miniconda3/envs/tf/lib/python3.9/runpy.py\", line 197, in _run_module_as_main\n      return _run_code(code, main_globals, None,\n    File \"/home/ubuntu/miniconda3/envs/tf/lib/python3.9/runpy.py\", line 87, in _run_code\n      exec(code, run_globals)\n    File \"/home/ubuntu/miniconda3/envs/tf/lib/python3.9/site-packages/ipykernel_launcher.py\", line 17, in <module>\n      app.launch_new_instance()\n    File \"/home/ubuntu/miniconda3/envs/tf/lib/python3.9/site-packages/traitlets/config/application.py\", line 992, in launch_instance\n      app.start()\n    File \"/home/ubuntu/miniconda3/envs/tf/lib/python3.9/site-packages/ipykernel/kernelapp.py\", line 711, in start\n      self.io_loop.start()\n    File \"/home/ubuntu/miniconda3/envs/tf/lib/python3.9/site-packages/tornado/platform/asyncio.py\", line 215, in start\n      self.asyncio_loop.run_forever()\n    File \"/home/ubuntu/miniconda3/envs/tf/lib/python3.9/asyncio/base_events.py\", line 601, in run_forever\n      self._run_once()\n    File \"/home/ubuntu/miniconda3/envs/tf/lib/python3.9/asyncio/base_events.py\", line 1905, in _run_once\n      handle._run()\n    File \"/home/ubuntu/miniconda3/envs/tf/lib/python3.9/asyncio/events.py\", line 80, in _run\n      self._context.run(self._callback, *self._args)\n    File \"/home/ubuntu/miniconda3/envs/tf/lib/python3.9/site-packages/ipykernel/kernelbase.py\", line 510, in dispatch_queue\n      await self.process_one()\n    File \"/home/ubuntu/miniconda3/envs/tf/lib/python3.9/site-packages/ipykernel/kernelbase.py\", line 499, in process_one\n      await dispatch(*args)\n    File \"/home/ubuntu/miniconda3/envs/tf/lib/python3.9/site-packages/ipykernel/kernelbase.py\", line 406, in dispatch_shell\n      await result\n    File \"/home/ubuntu/miniconda3/envs/tf/lib/python3.9/site-packages/ipykernel/kernelbase.py\", line 729, in execute_request\n      reply_content = await reply_content\n    File \"/home/ubuntu/miniconda3/envs/tf/lib/python3.9/site-packages/ipykernel/ipkernel.py\", line 411, in do_execute\n      res = shell.run_cell(\n    File \"/home/ubuntu/miniconda3/envs/tf/lib/python3.9/site-packages/ipykernel/zmqshell.py\", line 531, in run_cell\n      return super().run_cell(*args, **kwargs)\n    File \"/home/ubuntu/miniconda3/envs/tf/lib/python3.9/site-packages/IPython/core/interactiveshell.py\", line 3006, in run_cell\n      result = self._run_cell(\n    File \"/home/ubuntu/miniconda3/envs/tf/lib/python3.9/site-packages/IPython/core/interactiveshell.py\", line 3061, in _run_cell\n      result = runner(coro)\n    File \"/home/ubuntu/miniconda3/envs/tf/lib/python3.9/site-packages/IPython/core/async_helpers.py\", line 129, in _pseudo_sync_runner\n      coro.send(None)\n    File \"/home/ubuntu/miniconda3/envs/tf/lib/python3.9/site-packages/IPython/core/interactiveshell.py\", line 3266, in run_cell_async\n      has_raised = await self.run_ast_nodes(code_ast.body, cell_name,\n    File \"/home/ubuntu/miniconda3/envs/tf/lib/python3.9/site-packages/IPython/core/interactiveshell.py\", line 3445, in run_ast_nodes\n      if await self.run_code(code, result, async_=asy):\n    File \"/home/ubuntu/miniconda3/envs/tf/lib/python3.9/site-packages/IPython/core/interactiveshell.py\", line 3505, in run_code\n      exec(code_obj, self.user_global_ns, self.user_ns)\n    File \"/tmp/ipykernel_30336/2957581064.py\", line 1, in <module>\n      model.fit(x_train, final_y_train, batch_size=32, epochs=10, validation_data=(x_test,final_y_test))\n    File \"/home/ubuntu/miniconda3/envs/tf/lib/python3.9/site-packages/keras/utils/traceback_utils.py\", line 65, in error_handler\n      return fn(*args, **kwargs)\n    File \"/home/ubuntu/miniconda3/envs/tf/lib/python3.9/site-packages/keras/engine/training.py\", line 1685, in fit\n      tmp_logs = self.train_function(iterator)\n    File \"/home/ubuntu/miniconda3/envs/tf/lib/python3.9/site-packages/keras/engine/training.py\", line 1284, in train_function\n      return step_function(self, iterator)\n    File \"/home/ubuntu/miniconda3/envs/tf/lib/python3.9/site-packages/keras/engine/training.py\", line 1268, in step_function\n      outputs = model.distribute_strategy.run(run_step, args=(data,))\n    File \"/home/ubuntu/miniconda3/envs/tf/lib/python3.9/site-packages/keras/engine/training.py\", line 1249, in run_step\n      outputs = model.train_step(data)\n    File \"/home/ubuntu/miniconda3/envs/tf/lib/python3.9/site-packages/keras/engine/training.py\", line 1050, in train_step\n      y_pred = self(x, training=True)\n    File \"/home/ubuntu/miniconda3/envs/tf/lib/python3.9/site-packages/keras/utils/traceback_utils.py\", line 65, in error_handler\n      return fn(*args, **kwargs)\n    File \"/home/ubuntu/miniconda3/envs/tf/lib/python3.9/site-packages/keras/engine/training.py\", line 558, in __call__\n      return super().__call__(*args, **kwargs)\n    File \"/home/ubuntu/miniconda3/envs/tf/lib/python3.9/site-packages/keras/utils/traceback_utils.py\", line 65, in error_handler\n      return fn(*args, **kwargs)\n    File \"/home/ubuntu/miniconda3/envs/tf/lib/python3.9/site-packages/keras/engine/base_layer.py\", line 1145, in __call__\n      outputs = call_fn(inputs, *args, **kwargs)\n    File \"/home/ubuntu/miniconda3/envs/tf/lib/python3.9/site-packages/keras/utils/traceback_utils.py\", line 96, in error_handler\n      return fn(*args, **kwargs)\n    File \"/home/ubuntu/miniconda3/envs/tf/lib/python3.9/site-packages/keras/engine/sequential.py\", line 412, in call\n      return super().call(inputs, training=training, mask=mask)\n    File \"/home/ubuntu/miniconda3/envs/tf/lib/python3.9/site-packages/keras/engine/functional.py\", line 512, in call\n      return self._run_internal_graph(inputs, training=training, mask=mask)\n    File \"/home/ubuntu/miniconda3/envs/tf/lib/python3.9/site-packages/keras/engine/functional.py\", line 669, in _run_internal_graph\n      outputs = node.layer(*args, **kwargs)\n    File \"/home/ubuntu/miniconda3/envs/tf/lib/python3.9/site-packages/keras/utils/traceback_utils.py\", line 65, in error_handler\n      return fn(*args, **kwargs)\n    File \"/home/ubuntu/miniconda3/envs/tf/lib/python3.9/site-packages/keras/engine/base_layer.py\", line 1145, in __call__\n      outputs = call_fn(inputs, *args, **kwargs)\n    File \"/home/ubuntu/miniconda3/envs/tf/lib/python3.9/site-packages/keras/utils/traceback_utils.py\", line 96, in error_handler\n      return fn(*args, **kwargs)\n    File \"/home/ubuntu/miniconda3/envs/tf/lib/python3.9/site-packages/keras/layers/core/embedding.py\", line 272, in call\n      out = tf.nn.embedding_lookup(self.embeddings, inputs)\nNode: 'sequential/embedding/embedding_lookup'\nindices[20,205] = 7518 is not in [0, 5000)\n\t [[{{node sequential/embedding/embedding_lookup}}]] [Op:__inference_train_function_4240]"
     ]
    }
   ],
   "source": [
    "model.fit(x_train, final_y_train, batch_size=32, epochs=10, validation_data=(x_test,final_y_test))"
   ]
  },
  {
   "cell_type": "code",
   "execution_count": 23,
   "metadata": {},
   "outputs": [
    {
     "name": "stdout",
     "output_type": "stream",
     "text": [
      "Epoch 1/10\n"
     ]
    },
    {
     "name": "stderr",
     "output_type": "stream",
     "text": [
      "2023-04-08 19:45:40.715815: I tensorflow/core/common_runtime/executor.cc:1197] [/job:localhost/replica:0/task:0/device:CPU:0] (DEBUG INFO) Executor start aborting (this does not indicate an error and you can ignore this message): INVALID_ARGUMENT: indices[37,101] = 6656 is not in [0, 5000)\n",
      "\t [[{{node sequential/embedding/embedding_lookup}}]]\n"
     ]
    },
    {
     "ename": "InvalidArgumentError",
     "evalue": "Graph execution error:\n\nDetected at node 'sequential/embedding/embedding_lookup' defined at (most recent call last):\n    File \"/home/ubuntu/miniconda3/envs/tf/lib/python3.9/runpy.py\", line 197, in _run_module_as_main\n      return _run_code(code, main_globals, None,\n    File \"/home/ubuntu/miniconda3/envs/tf/lib/python3.9/runpy.py\", line 87, in _run_code\n      exec(code, run_globals)\n    File \"/home/ubuntu/miniconda3/envs/tf/lib/python3.9/site-packages/ipykernel_launcher.py\", line 17, in <module>\n      app.launch_new_instance()\n    File \"/home/ubuntu/miniconda3/envs/tf/lib/python3.9/site-packages/traitlets/config/application.py\", line 992, in launch_instance\n      app.start()\n    File \"/home/ubuntu/miniconda3/envs/tf/lib/python3.9/site-packages/ipykernel/kernelapp.py\", line 711, in start\n      self.io_loop.start()\n    File \"/home/ubuntu/miniconda3/envs/tf/lib/python3.9/site-packages/tornado/platform/asyncio.py\", line 215, in start\n      self.asyncio_loop.run_forever()\n    File \"/home/ubuntu/miniconda3/envs/tf/lib/python3.9/asyncio/base_events.py\", line 601, in run_forever\n      self._run_once()\n    File \"/home/ubuntu/miniconda3/envs/tf/lib/python3.9/asyncio/base_events.py\", line 1905, in _run_once\n      handle._run()\n    File \"/home/ubuntu/miniconda3/envs/tf/lib/python3.9/asyncio/events.py\", line 80, in _run\n      self._context.run(self._callback, *self._args)\n    File \"/home/ubuntu/miniconda3/envs/tf/lib/python3.9/site-packages/ipykernel/kernelbase.py\", line 510, in dispatch_queue\n      await self.process_one()\n    File \"/home/ubuntu/miniconda3/envs/tf/lib/python3.9/site-packages/ipykernel/kernelbase.py\", line 499, in process_one\n      await dispatch(*args)\n    File \"/home/ubuntu/miniconda3/envs/tf/lib/python3.9/site-packages/ipykernel/kernelbase.py\", line 406, in dispatch_shell\n      await result\n    File \"/home/ubuntu/miniconda3/envs/tf/lib/python3.9/site-packages/ipykernel/kernelbase.py\", line 729, in execute_request\n      reply_content = await reply_content\n    File \"/home/ubuntu/miniconda3/envs/tf/lib/python3.9/site-packages/ipykernel/ipkernel.py\", line 411, in do_execute\n      res = shell.run_cell(\n    File \"/home/ubuntu/miniconda3/envs/tf/lib/python3.9/site-packages/ipykernel/zmqshell.py\", line 531, in run_cell\n      return super().run_cell(*args, **kwargs)\n    File \"/home/ubuntu/miniconda3/envs/tf/lib/python3.9/site-packages/IPython/core/interactiveshell.py\", line 3006, in run_cell\n      result = self._run_cell(\n    File \"/home/ubuntu/miniconda3/envs/tf/lib/python3.9/site-packages/IPython/core/interactiveshell.py\", line 3061, in _run_cell\n      result = runner(coro)\n    File \"/home/ubuntu/miniconda3/envs/tf/lib/python3.9/site-packages/IPython/core/async_helpers.py\", line 129, in _pseudo_sync_runner\n      coro.send(None)\n    File \"/home/ubuntu/miniconda3/envs/tf/lib/python3.9/site-packages/IPython/core/interactiveshell.py\", line 3266, in run_cell_async\n      has_raised = await self.run_ast_nodes(code_ast.body, cell_name,\n    File \"/home/ubuntu/miniconda3/envs/tf/lib/python3.9/site-packages/IPython/core/interactiveshell.py\", line 3445, in run_ast_nodes\n      if await self.run_code(code, result, async_=asy):\n    File \"/home/ubuntu/miniconda3/envs/tf/lib/python3.9/site-packages/IPython/core/interactiveshell.py\", line 3505, in run_code\n      exec(code_obj, self.user_global_ns, self.user_ns)\n    File \"/tmp/ipykernel_30336/3697547531.py\", line 1, in <module>\n      model.fit(x_train, y_train, validation_data = (x_test,y_test), epochs = 10,batch_size = 64)\n    File \"/home/ubuntu/miniconda3/envs/tf/lib/python3.9/site-packages/keras/utils/traceback_utils.py\", line 65, in error_handler\n      return fn(*args, **kwargs)\n    File \"/home/ubuntu/miniconda3/envs/tf/lib/python3.9/site-packages/keras/engine/training.py\", line 1685, in fit\n      tmp_logs = self.train_function(iterator)\n    File \"/home/ubuntu/miniconda3/envs/tf/lib/python3.9/site-packages/keras/engine/training.py\", line 1284, in train_function\n      return step_function(self, iterator)\n    File \"/home/ubuntu/miniconda3/envs/tf/lib/python3.9/site-packages/keras/engine/training.py\", line 1268, in step_function\n      outputs = model.distribute_strategy.run(run_step, args=(data,))\n    File \"/home/ubuntu/miniconda3/envs/tf/lib/python3.9/site-packages/keras/engine/training.py\", line 1249, in run_step\n      outputs = model.train_step(data)\n    File \"/home/ubuntu/miniconda3/envs/tf/lib/python3.9/site-packages/keras/engine/training.py\", line 1050, in train_step\n      y_pred = self(x, training=True)\n    File \"/home/ubuntu/miniconda3/envs/tf/lib/python3.9/site-packages/keras/utils/traceback_utils.py\", line 65, in error_handler\n      return fn(*args, **kwargs)\n    File \"/home/ubuntu/miniconda3/envs/tf/lib/python3.9/site-packages/keras/engine/training.py\", line 558, in __call__\n      return super().__call__(*args, **kwargs)\n    File \"/home/ubuntu/miniconda3/envs/tf/lib/python3.9/site-packages/keras/utils/traceback_utils.py\", line 65, in error_handler\n      return fn(*args, **kwargs)\n    File \"/home/ubuntu/miniconda3/envs/tf/lib/python3.9/site-packages/keras/engine/base_layer.py\", line 1145, in __call__\n      outputs = call_fn(inputs, *args, **kwargs)\n    File \"/home/ubuntu/miniconda3/envs/tf/lib/python3.9/site-packages/keras/utils/traceback_utils.py\", line 96, in error_handler\n      return fn(*args, **kwargs)\n    File \"/home/ubuntu/miniconda3/envs/tf/lib/python3.9/site-packages/keras/engine/sequential.py\", line 412, in call\n      return super().call(inputs, training=training, mask=mask)\n    File \"/home/ubuntu/miniconda3/envs/tf/lib/python3.9/site-packages/keras/engine/functional.py\", line 512, in call\n      return self._run_internal_graph(inputs, training=training, mask=mask)\n    File \"/home/ubuntu/miniconda3/envs/tf/lib/python3.9/site-packages/keras/engine/functional.py\", line 669, in _run_internal_graph\n      outputs = node.layer(*args, **kwargs)\n    File \"/home/ubuntu/miniconda3/envs/tf/lib/python3.9/site-packages/keras/utils/traceback_utils.py\", line 65, in error_handler\n      return fn(*args, **kwargs)\n    File \"/home/ubuntu/miniconda3/envs/tf/lib/python3.9/site-packages/keras/engine/base_layer.py\", line 1145, in __call__\n      outputs = call_fn(inputs, *args, **kwargs)\n    File \"/home/ubuntu/miniconda3/envs/tf/lib/python3.9/site-packages/keras/utils/traceback_utils.py\", line 96, in error_handler\n      return fn(*args, **kwargs)\n    File \"/home/ubuntu/miniconda3/envs/tf/lib/python3.9/site-packages/keras/layers/core/embedding.py\", line 272, in call\n      out = tf.nn.embedding_lookup(self.embeddings, inputs)\nNode: 'sequential/embedding/embedding_lookup'\nindices[37,101] = 6656 is not in [0, 5000)\n\t [[{{node sequential/embedding/embedding_lookup}}]] [Op:__inference_train_function_6464]",
     "output_type": "error",
     "traceback": [
      "\u001b[0;31m---------------------------------------------------------------------------\u001b[0m",
      "\u001b[0;31mInvalidArgumentError\u001b[0m                      Traceback (most recent call last)",
      "Cell \u001b[0;32mIn[23], line 1\u001b[0m\n\u001b[0;32m----> 1\u001b[0m \u001b[43mmodel\u001b[49m\u001b[38;5;241;43m.\u001b[39;49m\u001b[43mfit\u001b[49m\u001b[43m(\u001b[49m\u001b[43mx_train\u001b[49m\u001b[43m,\u001b[49m\u001b[43m \u001b[49m\u001b[43my_train\u001b[49m\u001b[43m,\u001b[49m\u001b[43m \u001b[49m\u001b[43mvalidation_data\u001b[49m\u001b[43m \u001b[49m\u001b[38;5;241;43m=\u001b[39;49m\u001b[43m \u001b[49m\u001b[43m(\u001b[49m\u001b[43mx_test\u001b[49m\u001b[43m,\u001b[49m\u001b[43my_test\u001b[49m\u001b[43m)\u001b[49m\u001b[43m,\u001b[49m\u001b[43m \u001b[49m\u001b[43mepochs\u001b[49m\u001b[43m \u001b[49m\u001b[38;5;241;43m=\u001b[39;49m\u001b[43m \u001b[49m\u001b[38;5;241;43m10\u001b[39;49m\u001b[43m,\u001b[49m\u001b[43mbatch_size\u001b[49m\u001b[43m \u001b[49m\u001b[38;5;241;43m=\u001b[39;49m\u001b[43m \u001b[49m\u001b[38;5;241;43m64\u001b[39;49m\u001b[43m)\u001b[49m\n",
      "File \u001b[0;32m~/miniconda3/envs/tf/lib/python3.9/site-packages/keras/utils/traceback_utils.py:70\u001b[0m, in \u001b[0;36mfilter_traceback.<locals>.error_handler\u001b[0;34m(*args, **kwargs)\u001b[0m\n\u001b[1;32m     67\u001b[0m     filtered_tb \u001b[38;5;241m=\u001b[39m _process_traceback_frames(e\u001b[38;5;241m.\u001b[39m__traceback__)\n\u001b[1;32m     68\u001b[0m     \u001b[38;5;66;03m# To get the full stack trace, call:\u001b[39;00m\n\u001b[1;32m     69\u001b[0m     \u001b[38;5;66;03m# `tf.debugging.disable_traceback_filtering()`\u001b[39;00m\n\u001b[0;32m---> 70\u001b[0m     \u001b[38;5;28;01mraise\u001b[39;00m e\u001b[38;5;241m.\u001b[39mwith_traceback(filtered_tb) \u001b[38;5;28;01mfrom\u001b[39;00m \u001b[38;5;28mNone\u001b[39m\n\u001b[1;32m     71\u001b[0m \u001b[38;5;28;01mfinally\u001b[39;00m:\n\u001b[1;32m     72\u001b[0m     \u001b[38;5;28;01mdel\u001b[39;00m filtered_tb\n",
      "File \u001b[0;32m~/miniconda3/envs/tf/lib/python3.9/site-packages/tensorflow/python/eager/execute.py:52\u001b[0m, in \u001b[0;36mquick_execute\u001b[0;34m(op_name, num_outputs, inputs, attrs, ctx, name)\u001b[0m\n\u001b[1;32m     50\u001b[0m \u001b[38;5;28;01mtry\u001b[39;00m:\n\u001b[1;32m     51\u001b[0m   ctx\u001b[38;5;241m.\u001b[39mensure_initialized()\n\u001b[0;32m---> 52\u001b[0m   tensors \u001b[38;5;241m=\u001b[39m pywrap_tfe\u001b[38;5;241m.\u001b[39mTFE_Py_Execute(ctx\u001b[38;5;241m.\u001b[39m_handle, device_name, op_name,\n\u001b[1;32m     53\u001b[0m                                       inputs, attrs, num_outputs)\n\u001b[1;32m     54\u001b[0m \u001b[38;5;28;01mexcept\u001b[39;00m core\u001b[38;5;241m.\u001b[39m_NotOkStatusException \u001b[38;5;28;01mas\u001b[39;00m e:\n\u001b[1;32m     55\u001b[0m   \u001b[38;5;28;01mif\u001b[39;00m name \u001b[38;5;129;01mis\u001b[39;00m \u001b[38;5;129;01mnot\u001b[39;00m \u001b[38;5;28;01mNone\u001b[39;00m:\n",
      "\u001b[0;31mInvalidArgumentError\u001b[0m: Graph execution error:\n\nDetected at node 'sequential/embedding/embedding_lookup' defined at (most recent call last):\n    File \"/home/ubuntu/miniconda3/envs/tf/lib/python3.9/runpy.py\", line 197, in _run_module_as_main\n      return _run_code(code, main_globals, None,\n    File \"/home/ubuntu/miniconda3/envs/tf/lib/python3.9/runpy.py\", line 87, in _run_code\n      exec(code, run_globals)\n    File \"/home/ubuntu/miniconda3/envs/tf/lib/python3.9/site-packages/ipykernel_launcher.py\", line 17, in <module>\n      app.launch_new_instance()\n    File \"/home/ubuntu/miniconda3/envs/tf/lib/python3.9/site-packages/traitlets/config/application.py\", line 992, in launch_instance\n      app.start()\n    File \"/home/ubuntu/miniconda3/envs/tf/lib/python3.9/site-packages/ipykernel/kernelapp.py\", line 711, in start\n      self.io_loop.start()\n    File \"/home/ubuntu/miniconda3/envs/tf/lib/python3.9/site-packages/tornado/platform/asyncio.py\", line 215, in start\n      self.asyncio_loop.run_forever()\n    File \"/home/ubuntu/miniconda3/envs/tf/lib/python3.9/asyncio/base_events.py\", line 601, in run_forever\n      self._run_once()\n    File \"/home/ubuntu/miniconda3/envs/tf/lib/python3.9/asyncio/base_events.py\", line 1905, in _run_once\n      handle._run()\n    File \"/home/ubuntu/miniconda3/envs/tf/lib/python3.9/asyncio/events.py\", line 80, in _run\n      self._context.run(self._callback, *self._args)\n    File \"/home/ubuntu/miniconda3/envs/tf/lib/python3.9/site-packages/ipykernel/kernelbase.py\", line 510, in dispatch_queue\n      await self.process_one()\n    File \"/home/ubuntu/miniconda3/envs/tf/lib/python3.9/site-packages/ipykernel/kernelbase.py\", line 499, in process_one\n      await dispatch(*args)\n    File \"/home/ubuntu/miniconda3/envs/tf/lib/python3.9/site-packages/ipykernel/kernelbase.py\", line 406, in dispatch_shell\n      await result\n    File \"/home/ubuntu/miniconda3/envs/tf/lib/python3.9/site-packages/ipykernel/kernelbase.py\", line 729, in execute_request\n      reply_content = await reply_content\n    File \"/home/ubuntu/miniconda3/envs/tf/lib/python3.9/site-packages/ipykernel/ipkernel.py\", line 411, in do_execute\n      res = shell.run_cell(\n    File \"/home/ubuntu/miniconda3/envs/tf/lib/python3.9/site-packages/ipykernel/zmqshell.py\", line 531, in run_cell\n      return super().run_cell(*args, **kwargs)\n    File \"/home/ubuntu/miniconda3/envs/tf/lib/python3.9/site-packages/IPython/core/interactiveshell.py\", line 3006, in run_cell\n      result = self._run_cell(\n    File \"/home/ubuntu/miniconda3/envs/tf/lib/python3.9/site-packages/IPython/core/interactiveshell.py\", line 3061, in _run_cell\n      result = runner(coro)\n    File \"/home/ubuntu/miniconda3/envs/tf/lib/python3.9/site-packages/IPython/core/async_helpers.py\", line 129, in _pseudo_sync_runner\n      coro.send(None)\n    File \"/home/ubuntu/miniconda3/envs/tf/lib/python3.9/site-packages/IPython/core/interactiveshell.py\", line 3266, in run_cell_async\n      has_raised = await self.run_ast_nodes(code_ast.body, cell_name,\n    File \"/home/ubuntu/miniconda3/envs/tf/lib/python3.9/site-packages/IPython/core/interactiveshell.py\", line 3445, in run_ast_nodes\n      if await self.run_code(code, result, async_=asy):\n    File \"/home/ubuntu/miniconda3/envs/tf/lib/python3.9/site-packages/IPython/core/interactiveshell.py\", line 3505, in run_code\n      exec(code_obj, self.user_global_ns, self.user_ns)\n    File \"/tmp/ipykernel_30336/3697547531.py\", line 1, in <module>\n      model.fit(x_train, y_train, validation_data = (x_test,y_test), epochs = 10,batch_size = 64)\n    File \"/home/ubuntu/miniconda3/envs/tf/lib/python3.9/site-packages/keras/utils/traceback_utils.py\", line 65, in error_handler\n      return fn(*args, **kwargs)\n    File \"/home/ubuntu/miniconda3/envs/tf/lib/python3.9/site-packages/keras/engine/training.py\", line 1685, in fit\n      tmp_logs = self.train_function(iterator)\n    File \"/home/ubuntu/miniconda3/envs/tf/lib/python3.9/site-packages/keras/engine/training.py\", line 1284, in train_function\n      return step_function(self, iterator)\n    File \"/home/ubuntu/miniconda3/envs/tf/lib/python3.9/site-packages/keras/engine/training.py\", line 1268, in step_function\n      outputs = model.distribute_strategy.run(run_step, args=(data,))\n    File \"/home/ubuntu/miniconda3/envs/tf/lib/python3.9/site-packages/keras/engine/training.py\", line 1249, in run_step\n      outputs = model.train_step(data)\n    File \"/home/ubuntu/miniconda3/envs/tf/lib/python3.9/site-packages/keras/engine/training.py\", line 1050, in train_step\n      y_pred = self(x, training=True)\n    File \"/home/ubuntu/miniconda3/envs/tf/lib/python3.9/site-packages/keras/utils/traceback_utils.py\", line 65, in error_handler\n      return fn(*args, **kwargs)\n    File \"/home/ubuntu/miniconda3/envs/tf/lib/python3.9/site-packages/keras/engine/training.py\", line 558, in __call__\n      return super().__call__(*args, **kwargs)\n    File \"/home/ubuntu/miniconda3/envs/tf/lib/python3.9/site-packages/keras/utils/traceback_utils.py\", line 65, in error_handler\n      return fn(*args, **kwargs)\n    File \"/home/ubuntu/miniconda3/envs/tf/lib/python3.9/site-packages/keras/engine/base_layer.py\", line 1145, in __call__\n      outputs = call_fn(inputs, *args, **kwargs)\n    File \"/home/ubuntu/miniconda3/envs/tf/lib/python3.9/site-packages/keras/utils/traceback_utils.py\", line 96, in error_handler\n      return fn(*args, **kwargs)\n    File \"/home/ubuntu/miniconda3/envs/tf/lib/python3.9/site-packages/keras/engine/sequential.py\", line 412, in call\n      return super().call(inputs, training=training, mask=mask)\n    File \"/home/ubuntu/miniconda3/envs/tf/lib/python3.9/site-packages/keras/engine/functional.py\", line 512, in call\n      return self._run_internal_graph(inputs, training=training, mask=mask)\n    File \"/home/ubuntu/miniconda3/envs/tf/lib/python3.9/site-packages/keras/engine/functional.py\", line 669, in _run_internal_graph\n      outputs = node.layer(*args, **kwargs)\n    File \"/home/ubuntu/miniconda3/envs/tf/lib/python3.9/site-packages/keras/utils/traceback_utils.py\", line 65, in error_handler\n      return fn(*args, **kwargs)\n    File \"/home/ubuntu/miniconda3/envs/tf/lib/python3.9/site-packages/keras/engine/base_layer.py\", line 1145, in __call__\n      outputs = call_fn(inputs, *args, **kwargs)\n    File \"/home/ubuntu/miniconda3/envs/tf/lib/python3.9/site-packages/keras/utils/traceback_utils.py\", line 96, in error_handler\n      return fn(*args, **kwargs)\n    File \"/home/ubuntu/miniconda3/envs/tf/lib/python3.9/site-packages/keras/layers/core/embedding.py\", line 272, in call\n      out = tf.nn.embedding_lookup(self.embeddings, inputs)\nNode: 'sequential/embedding/embedding_lookup'\nindices[37,101] = 6656 is not in [0, 5000)\n\t [[{{node sequential/embedding/embedding_lookup}}]] [Op:__inference_train_function_6464]"
     ]
    }
   ],
   "source": [
    "model.fit(x_train, y_train, validation_data = (x_test,y_test), epochs = 10,batch_size = 64)"
   ]
  }
 ],
 "metadata": {
  "colab": {
   "provenance": []
  },
  "kernelspec": {
   "display_name": "Python [conda env:tf] *",
   "language": "python",
   "name": "conda-env-tf-py"
  },
  "language_info": {
   "codemirror_mode": {
    "name": "ipython",
    "version": 3
   },
   "file_extension": ".py",
   "mimetype": "text/x-python",
   "name": "python",
   "nbconvert_exporter": "python",
   "pygments_lexer": "ipython3",
   "version": "3.9.16"
  }
 },
 "nbformat": 4,
 "nbformat_minor": 1
}
